Workbook

Sheet Product Price
A1: รุ่น/รายละเอียด | B1: ราคา | C1: image link | D1: Helper | F1: Brand | G1: File Name
A2: HONOR Magic V6 16/512 GB | B2: 67999 | C2: 161 | D2: =IF(OR($A2="",LEFT($A2,1)="*"),"",IF('Detail Price'!$A$2="All",ROW(),IF(LEFT($A2,LEN('Detail Price'!$A$2))='Detail Price'!$A$2,ROW(),""))) -> 2 | F2: HONOR | G2: AddedArtboard 3AM2
A3: HONOR Magic8 Pro 12/512 GB | B3: 39990 | C3: 1 | D3: =IF(OR($A3="",LEFT($A3,1)="*"),"",IF('Detail Price'!$A$2="All",ROW(),IF(LEFT($A3,LEN('Detail Price'!$A$2))='Detail Price'!$A$2,ROW(),""))) -> 3 | F3: HUAWEI | G3: AddedArtboard 4AM2
A4: HONOR X6d 4/128 GB | B4: 5999 | C4: 2 | D4: =IF(OR($A4="",LEFT($A4,1)="*"),"",IF('Detail Price'!$A$2="All",ROW(),IF(LEFT($A4,LEN('Detail Price'!$A$2))='Detail Price'!$A$2,ROW(),""))) -> 4 | F4: INFINIX | G4: AddedArtboard 6AM2
A5: HONOR 600 Lite 5G 8/256 GB | B5: 13999 | C5: 3 | D5: =IF(OR($A5="",LEFT($A5,1)="*"),"",IF('Detail Price'!$A$2="All",ROW(),IF(LEFT($A5,LEN('Detail Price'!$A$2))='Detail Price'!$A$2,ROW(),""))) -> 5 | F5: Nubia | G5: AddedArtboard 7AM2
A6: HONOR 600 5G 12/256 GB | B6: 19999 | C6: 4 | D6: =IF(OR($A6="",LEFT($A6,1)="*"),"",IF('Detail Price'!$A$2="All",ROW(),IF(LEFT($A6,LEN('Detail Price'!$A$2))='Detail Price'!$A$2,ROW(),""))) -> 6 | F6: Realme | G6: AddedArtboard 5AM2
A7: HONOR 600 Pro 5G 12/512 GB | B7: 29999 | C7: 5 | D7: =IF(OR($A7="",LEFT($A7,1)="*"),"",IF('Detail Price'!$A$2="All",ROW(),IF(LEFT($A7,LEN('Detail Price'!$A$2))='Detail Price'!$A$2,ROW(),""))) -> 7 | F7: Samsung | G7: AddedArtboard 2AM2
A8: HONOR X7e 6/256 GB | B8: 8999 | C8: 159 | D8: =IF(OR($A8="",LEFT($A8,1)="*"),"",IF('Detail Price'!$A$2="All",ROW(),IF(LEFT($A8,LEN('Detail Price'!$A$2))='Detail Price'!$A$2,ROW(),""))) -> 8 | F8: TECNO | G8: AddedArtboard 5Layout
A9: HONOR X7e 6/128 GB | B9: 7999 | C9: 160 | D9: =IF(OR($A9="",LEFT($A9,1)="*"),"",IF('Detail Price'!$A$2="All",ROW(),IF(LEFT($A9,LEN('Detail Price'!$A$2))='Detail Price'!$A$2,ROW(),""))) -> 9 | F9: REDMI | G9: AddedArtboard 8AM2
A10: HONOR Pad X8b 6/128 GB | B10: 8999 | C10: 6 | D10: =IF(OR($A10="",LEFT($A10,1)="*"),"",IF('Detail Price'!$A$2="All",ROW(),IF(LEFT($A10,LEN('Detail Price'!$A$2))='Detail Price'!$A$2,ROW(),""))) -> 10 | F10: XIAOMI | G10: AddedArtboard 9AM2
A11: HUAWEI Mate X7 16/512 GB | B11: 59990 | C11: 7 | D11: =IF(OR($A11="",LEFT($A11,1)="*"),"",IF('Detail Price'!$A$2="All",ROW(),IF(LEFT($A11,LEN('Detail Price'!$A$2))='Detail Price'!$A$2,ROW(),""))) -> 11 | F11: OPPO | G11: AddedArtboard 10AM2
A12: HUAWEI Pura 90s ProMax 12/512 GB | B12: 49990 | C12: 177 | D12: =IF(OR($A12="",LEFT($A12,1)="*"),"",IF('Detail Price'!$A$2="All",ROW(),IF(LEFT($A12,LEN('Detail Price'!$A$2))='Detail Price'!$A$2,ROW(),""))) -> 12 | F12: vivo | G12: AddedArtboard 11AM2
A13: HUAWEI Pura 90s 12/512 GB | B13: 38990 | C13: 178 | D13: =IF(OR($A13="",LEFT($A13,1)="*"),"",IF('Detail Price'!$A$2="All",ROW(),IF(LEFT($A13,LEN('Detail Price'!$A$2))='Detail Price'!$A$2,ROW(),""))) -> 13 | F13: iQOO | G13: AddedArtboard 12AM2
A14: HUAWEI Pura 90s 12/256 GB | B14: 34990 | C14: 179 | D14: =IF(OR($A14="",LEFT($A14,1)="*"),"",IF('Detail Price'!$A$2="All",ROW(),IF(LEFT($A14,LEN('Detail Price'!$A$2))='Detail Price'!$A$2,ROW(),""))) -> 14
A15: HUAWEI 80 Pro 16/512 GB | B15: 37990 | C15: 8 | D15: =IF(OR($A15="",LEFT($A15,1)="*"),"",IF('Detail Price'!$A$2="All",ROW(),IF(LEFT($A15,LEN('Detail Price'!$A$2))='Detail Price'!$A$2,ROW(),""))) -> 15
A16: HUAWEI Pura 80 Ultra 16/512 GB | B16: 39990 | C16: 9 | D16: =IF(OR($A16="",LEFT($A16,1)="*"),"",IF('Detail Price'!$A$2="All",ROW(),IF(LEFT($A16,LEN('Detail Price'!$A$2))='Detail Price'!$A$2,ROW(),""))) -> 16
A17: HUAWEI Pura 80 Pro 12/512 GB | B17: 29990 | C17: 10 | D17: =IF(OR($A17="",LEFT($A17,1)="*"),"",IF('Detail Price'!$A$2="All",ROW(),IF(LEFT($A17,LEN('Detail Price'!$A$2))='Detail Price'!$A$2,ROW(),""))) -> 17
A18: HUAWEI Pura 80 12/256 GB | B18: 19990 | C18: 11 | D18: =IF(OR($A18="",LEFT($A18,1)="*"),"",IF('Detail Price'!$A$2="All",ROW(),IF(LEFT($A18,LEN('Detail Price'!$A$2))='Detail Price'!$A$2,ROW(),""))) -> 18
A19: HUAWEI Nova 14 Pro 12/512 GB | B19: 15990 | C19: 12 | D19: =IF(OR($A19="",LEFT($A19,1)="*"),"",IF('Detail Price'!$A$2="All",ROW(),IF(LEFT($A19,LEN('Detail Price'!$A$2))='Detail Price'!$A$2,ROW(),""))) -> 19
A20: HUAWEI Nova 14 12/256 GB | B20: 11990 | C20: 13 | D20: =IF(OR($A20="",LEFT($A20,1)="*"),"",IF('Detail Price'!$A$2="All",ROW(),IF(LEFT($A20,LEN('Detail Price'!$A$2))='Detail Price'!$A$2,ROW(),""))) -> 20
A21: HUAWEI Nova Y73 8/256 GB | B21: 5990 | C21: 14 | D21: =IF(OR($A21="",LEFT($A21,1)="*"),"",IF('Detail Price'!$A$2="All",ROW(),IF(LEFT($A21,LEN('Detail Price'!$A$2))='Detail Price'!$A$2,ROW(),""))) -> 21
A22: HUAWEI MatePad ProMax 12/512 GB | B22: 52990 | C22: 180 | D22: =IF(OR($A22="",LEFT($A22,1)="*"),"",IF('Detail Price'!$A$2="All",ROW(),IF(LEFT($A22,LEN('Detail Price'!$A$2))='Detail Price'!$A$2,ROW(),""))) -> 22
A23: HUAWEI MatePad ProMax 12/256 GB | B23: 39990 | C23: 181 | D23: =IF(OR($A23="",LEFT($A23,1)="*"),"",IF('Detail Price'!$A$2="All",ROW(),IF(LEFT($A23,LEN('Detail Price'!$A$2))='Detail Price'!$A$2,ROW(),""))) -> 23
A24: HUAWEI MatePad Pro 13.2 12/512 GB | B24: 32990 | C24: 15 | D24: =IF(OR($A24="",LEFT($A24,1)="*"),"",IF('Detail Price'!$A$2="All",ROW(),IF(LEFT($A24,LEN('Detail Price'!$A$2))='Detail Price'!$A$2,ROW(),""))) -> 24
A25: HUAWEI MatePad Pro 12.2 2025 12/512 GB | B25: 27990 | C25: 16 | D25: =IF(OR($A25="",LEFT($A25,1)="*"),"",IF('Detail Price'!$A$2="All",ROW(),IF(LEFT($A25,LEN('Detail Price'!$A$2))='Detail Price'!$A$2,ROW(),""))) -> 25
... A265: iQOO Z11x 8/128 GB | B265: 9900 | C265: 248 | D265: =IF(OR($A265="",LEFT($A265,1)="*"),"",IF('Detail Price'!$A$2="All",ROW(),IF(LEFT($A265,LEN('Detail Price'!$A$2))='Detail Price'!$A$2,ROW(),""))) -> 265

Sheet Detail Price
A1: 0.0115 | B1: 400 | C1: 0
A2: All | B2: Price | C2: Image Link | D2: Insurance | E2: price+ins | F2: Down 15% | G2: FA | H2: FA+Ins | I2: 6 เดือน | J2: 9 เดือน | K2: 12 เดือน | L2: 15 เดือน | M2: 18 เดือน | N2: 24 เดือน | O2: Down 20% | P2: FA | Q2: FA+Ins | R2: 6 เดือน | S2: 9 เดือน | T2: 12 เดือน | U2: 15 เดือน | V2: 18 เดือน | W2: 24 เดือน | X2: Down 25% | Y2: FA | Z2: FA+Ins | AA2: 6 เดือน | AB2: 9 เดือน | AC2: 12 เดือน | AD2: 15 เดือน | AE2: 18 เดือน | AF2: 24 เดือน | AG2: Down 35% | AH2: FA | AI2: FA+Ins | AJ2: 6 เดือน | AK2: 9 เดือน | AL2: 12 เดือน | AM2: 15 เดือน | AN2: 18 เดือน | AO2: 24 เดือน | AP2: Down 40% | AQ2: FA | AR2: FA+Ins | AS2: 6 เดือน | AT2: 9 เดือน | AU2: 12 เดือน | AV2: 15 เดือน | AW2: 18 เดือน | AX2: 24 เดือน
A3: {=IFERROR(INDEX('Product Price'!A:A,SMALL('Product Price'!$D:$D,1)),"")} -> HONOR Magic V6 16/512 GB | B3: {=IFERROR(INDEX('Product Price'!B:B,SMALL('Product Price'!$D:$D,1)),"")} -> 67999 | C3: {=IFERROR(INDEX('Product Price'!C:C,SMALL('Product Price'!$D:$D,1)),"")} -> 161 | D3: =IF(AND(B3>=3900,B3<=10000),795,IF(AND(B3>=10001,B3<=20000),1450,IF(AND(B3>=20001,B3<=40000),1900,IF(AND(B3>=40001,B3<=60000),2475,IF(AND(B3>=60001,B3<=80000),4025,IF(AND(B3>=80001,B3<=100000),5175,IF(AND(B3>=100001,B3<=120000),6785,""))))))) -> 4025 | E3: =IFERROR(B3+D3,"") -> 72024 | F3: =IFERROR(ROUNDUP($B3*15%,0),"") -> 10200 | G3: =$B3-F3 -> 57799 | H3: =$G3+D3 -> 61824 | I3: =IF(((G3*$A$1)*6)<$C$1,"-",IF(ROUNDUP((((G3*100/107)*(1+($A$1*6)))/6)*1.07,0)<$B$1,"-",ROUNDUP(((((G3*100/107)+$D3)*(1+($A$1*6)))/6)*1.07,0))) -> 11066 | J3: =IF(((G3*$A$1)*9)<$C$1,"-",IF(ROUNDUP((((G3*100/107)*(1+($A$1*9)))/9)*1.07,0)<$B$1,"-",ROUNDUP(((((G3*100/107)+$D3)*(1+($A$1*9)))/9)*1.07,0))) -> 7615 | K3: =IF(((G3*$A$1)*12)<$C$1,"-",IF(ROUNDUP((((G3*100/107)*(1+($A$1*12)))/12)*1.07,0)<$B$1,"-",ROUNDUP(((((G3*100/107)+$D3)*(1+($A$1*12)))/12)*1.07,0))) -> 5890 | L3: =IF(((G3*$A$1)*15)<$C$1,"-",IF(ROUNDUP((((G3*100/107)*(1+($A$1*15)))/15)*1.07,0)<$B$1,"-",ROUNDUP(((((G3*100/107)+$D3)*(1+($A$1*15)))/15)*1.07,0))) -> 4855 | M3: =IF(((G3*$A$1)*18)<$C$1,"-",IF(ROUNDUP((((G3*100/107)*(1+($A$1*18)))/18)*1.07,0)<$B$1,"-",ROUNDUP(((((G3*100/107)+$D3)*(1+($A$1*18)))/18)*1.07,0))) -> 4165 | N3: =IF(((G3*$A$1)*24)<$C$1,"-",IF(ROUNDUP((((G3*100/107)*(1+($A$1*24)))/24)*1.07,0)<$B$1,"-",ROUNDUP(((((G3*100/107)+$D3)*(1+($A$1*24)))/24)*1.07,0))) -> 3302 | O3: =ROUNDUP($B3*20%,0) -> 13600 | P3: =$B3-O3 -> 54399 | Q3: =P3+$D3 -> 58424 | R3: =IF(((P3*$A$1)*6)<$C$1,"-",IF(ROUNDUP((((P3*100/107)*(1+($A$1*6)))/6)*1.07,0)<$B$1,"-",ROUNDUP(((((P3*100/107)+$D3)*(1+($A$1*6)))/6)*1.07,0))) -> 10460 | S3: =IF(((P3*$A$1)*9)<$C$1,"-",IF(ROUNDUP((((P3*100/107)*(1+($A$1*9)))/9)*1.07,0)<$B$1,"-",ROUNDUP(((((P3*100/107)+$D3)*(1+($A$1*9)))/9)*1.07,0))) -> 7198 | T3: =IF(((P3*$A$1)*12)<$C$1,"-",IF(ROUNDUP((((P3*100/107)*(1+($A$1*12)))/12)*1.07,0)<$B$1,"-",ROUNDUP(((((P3*100/107)+$D3)*(1+($A$1*12)))/12)*1.07,0))) -> 5568 | U3: =IF(((P3*$A$1)*15)<$C$1,"-",IF(ROUNDUP((((P3*100/107)*(1+($A$1*15)))/15)*1.07,0)<$B$1,"-",ROUNDUP(((((P3*100/107)+$D3)*(1+($A$1*15)))/15)*1.07,0))) -> 4589 | V3: =IF(((P3*$A$1)*18)<$C$1,"-",IF(ROUNDUP((((P3*100/107)*(1+($A$1*18)))/18)*1.07,0)<$B$1,"-",ROUNDUP(((((P3*100/107)+$D3)*(1+($A$1*18)))/18)*1.07,0))) -> 3937 | W3: =IF(((P3*$A$1)*24)<$C$1,"-",IF(ROUNDUP((((P3*100/107)*(1+($A$1*24)))/24)*1.07,0)<$B$1,"-",ROUNDUP(((((P3*100/107)+$D3)*(1+($A$1*24)))/24)*1.07,0))) -> 3122 | X3: =ROUNDUP($B3*25%,0) -> 17000 | Y3: =$B3-X3 -> 50999 | Z3: =Y3+$D3 -> 55024 | AA3: =IF(((Y3*$A$1)*6)<$C$1,"-",IF(ROUNDUP((((Y3*100/107)*(1+($A$1*6)))/6)*1.07,0)<$B$1,"-",ROUNDUP(((((Y3*100/107)+$D3)*(1+($A$1*6)))/6)*1.07,0))) -> 9854 | AB3: =IF(((Y3*$A$1)*9)<$C$1,"-",IF(ROUNDUP((((Y3*100/107)*(1+($A$1*9)))/9)*1.07,0)<$B$1,"-",ROUNDUP(((((Y3*100/107)+$D3)*(1+($A$1*9)))/9)*1.07,0))) -> 6782 | AC3: =IF(((Y3*$A$1)*12)<$C$1,"-",IF(ROUNDUP((((Y3*100/107)*(1+($A$1*12)))/12)*1.07,0)<$B$1,"-",ROUNDUP(((((Y3*100/107)+$D3)*(1+($A$1*12)))/12)*1.07,0))) -> 5245 | AD3: =IF(((Y3*$A$1)*15)<$C$1,"-",IF(ROUNDUP((((Y3*100/107)*(1+($A$1*15)))/15)*1.07,0)<$B$1,"-",ROUNDUP(((((Y3*100/107)+$D3)*(1+($A$1*15)))/15)*1.07,0))) -> 4324 | AE3: =IF(((Y3*$A$1)*18)<$C$1,"-",IF(ROUNDUP((((Y3*100/107)*(1+($A$1*18)))/18)*1.07,0)<$B$1,"-",ROUNDUP(((((Y3*100/107)+$D3)*(1+($A$1*18)))/18)*1.07,0))) -> 3709 | AF3: =IF(((Y3*$A$1)*24)<$C$1,"-",IF(ROUNDUP((((Y3*100/107)*(1+($A$1*24)))/24)*1.07,0)<$B$1,"-",ROUNDUP(((((Y3*100/107)+$D3)*(1+($A$1*24)))/24)*1.07,0))) -> 2941 | AG3: =ROUNDUP($B3*35%,0) -> 23800 | AH3: =$B3-AG3 -> 44199 | AI3: =AH3+$D3 -> 48224 | AJ3: =IF(((AH3*$A$1)*6)<$C$1,"-",IF(ROUNDUP((((AH3*100/107)*(1+($A$1*6)))/6)*1.07,0)<$B$1,"-",ROUNDUP(((((AH3*100/107)+$D3)*(1+($A$1*6)))/6)*1.07,0))) -> 8643 | AK3: =IF(((AH3*$A$1)*9)<$C$1,"-",IF(ROUNDUP((((AH3*100/107)*(1+($A$1*9)))/9)*1.07,0)<$B$1,"-",ROUNDUP(((((AH3*100/107)+$D3)*(1+($A$1*9)))/9)*1.07,0))) -> 5948 | AL3: =IF(((AH3*$A$1)*12)<$C$1,"-",IF(ROUNDUP((((AH3*100/107)*(1+($A$1*12)))/12)*1.07,0)<$B$1,"-",ROUNDUP(((((AH3*100/107)+$D3)*(1+($A$1*12)))/12)*1.07,0))) -> 4600 | AM3: =IF(((AH3*$A$1)*15)<$C$1,"-",IF(ROUNDUP((((AH3*100/107)*(1+($A$1*15)))/15)*1.07,0)<$B$1,"-",ROUNDUP(((((AH3*100/107)+$D3)*(1+($A$1*15)))/15)*1.07,0))) -> 3792 | AN3: =IF(((AH3*$A$1)*18)<$C$1,"-",IF(ROUNDUP((((AH3*100/107)*(1+($A$1*18)))/18)*1.07,0)<$B$1,"-",ROUNDUP(((((AH3*100/107)+$D3)*(1+($A$1*18)))/18)*1.07,0))) -> 3253 | AO3: =IF(((AH3*$A$1)*24)<$C$1,"-",IF(ROUNDUP((((AH3*100/107)*(1+($A$1*24)))/24)*1.07,0)<$B$1,"-",ROUNDUP(((((AH3*100/107)+$D3)*(1+($A$1*24)))/24)*1.07,0))) -> 2579 | AP3: =ROUNDUP($B3*40%,0) -> 27200 | AQ3: =$B3-AP3 -> 40799 | AR3: =AQ3+$D3 -> 44824 | AS3: =IF(((AQ3*$A$1)*6)<$C$1,"-",IF(ROUNDUP((((AQ3*100/107)*(1+($A$1*6)))/6)*1.07,0)<$B$1,"-",ROUNDUP(((((AQ3*100/107)+$D3)*(1+($A$1*6)))/6)*1.07,0))) -> 8037 | AT3: =IF(((AQ3*$A$1)*9)<$C$1,"-",IF(ROUNDUP((((AQ3*100/107)*(1+($A$1*9)))/9)*1.07,0)<$B$1,"-",ROUNDUP(((((AQ3*100/107)+$D3)*(1+($A$1*9)))/9)*1.07,0))) -> 5531 | AU3: =IF(((AQ3*$A$1)*12)<$C$1,"-",IF(ROUNDUP((((AQ3*100/107)*(1+($A$1*12)))/12)*1.07,0)<$B$1,"-",ROUNDUP(((((AQ3*100/107)+$D3)*(1+($A$1*12)))/12)*1.07,0))) -> 4278 | AV3: =IF(((AQ3*$A$1)*15)<$C$1,"-",IF(ROUNDUP((((AQ3*100/107)*(1+($A$1*15)))/15)*1.07,0)<$B$1,"-",ROUNDUP(((((AQ3*100/107)+$D3)*(1+($A$1*15)))/15)*1.07,0))) -> 3526 | AW3: =IF(((AQ3*$A$1)*18)<$C$1,"-",IF(ROUNDUP((((AQ3*100/107)*(1+($A$1*18)))/18)*1.07,0)<$B$1,"-",ROUNDUP(((((AQ3*100/107)+$D3)*(1+($A$1*18)))/18)*1.07,0))) -> 3025 | AX3: =IF(((AQ3*$A$1)*24)<$C$1,"-",IF(ROUNDUP((((AQ3*100/107)*(1+($A$1*24)))/24)*1.07,0)<$B$1,"-",ROUNDUP(((((AQ3*100/107)+$D3)*(1+($A$1*24)))/24)*1.07,0))) -> 2399
A4: {=IFERROR(INDEX('Product Price'!A:A,SMALL('Product Price'!$D:$D,2)),"")} -> HONOR Magic8 Pro 12/512 GB | B4: {=IFERROR(INDEX('Product Price'!B:B,SMALL('Product Price'!$D:$D,2)),"")} -> 39990 | C4: {=IFERROR(INDEX('Product Price'!C:C,SMALL('Product Price'!$D:$D,2)),"")} -> 1 | D4: =IF(AND(B4>=3900,B4<=10000),795,IF(AND(B4>=10001,B4<=20000),1450,IF(AND(B4>=20001,B4<=40000),1900,IF(AND(B4>=40001,B4<=60000),2475,IF(AND(B4>=60001,B4<=80000),4025,IF(AND(B4>=80001,B4<=100000),5175,IF(AND(B4>=100001,B4<=120000),6785,""))))))) -> 1900 | E4: =IFERROR(B4+D4,"") -> 41890 | F4: =IFERROR(ROUNDUP($B4*15%,0),"") -> 5999 | G4: =$B4-F4 -> 33991 | H4: =$G4+D4 -> 35891 | I4: =IF(((G4*$A$1)*6)<$C$1,"-",IF(ROUNDUP((((G4*100/107)*(1+($A$1*6)))/6)*1.07,0)<$B$1,"-",ROUNDUP(((((G4*100/107)+$D4)*(1+($A$1*6)))/6)*1.07,0))) -> 6419 | J4: =IF(((G4*$A$1)*9)<$C$1,"-",IF(ROUNDUP((((G4*100/107)*(1+($A$1*9)))/9)*1.07,0)<$B$1,"-",ROUNDUP(((((G4*100/107)+$D4)*(1+($A$1*9)))/9)*1.07,0))) -> 4417 | K4: =IF(((G4*$A$1)*12)<$C$1,"-",IF(ROUNDUP((((G4*100/107)*(1+($A$1*12)))/12)*1.07,0)<$B$1,"-",ROUNDUP(((((G4*100/107)+$D4)*(1+($A$1*12)))/12)*1.07,0))) -> 3417 | L4: =IF(((G4*$A$1)*15)<$C$1,"-",IF(ROUNDUP((((G4*100/107)*(1+($A$1*15)))/15)*1.07,0)<$B$1,"-",ROUNDUP(((((G4*100/107)+$D4)*(1+($A$1*15)))/15)*1.07,0))) -> 2816 | M4: =IF(((G4*$A$1)*18)<$C$1,"-",IF(ROUNDUP((((G4*100/107)*(1+($A$1*18)))/18)*1.07,0)<$B$1,"-",ROUNDUP(((((G4*100/107)+$D4)*(1+($A$1*18)))/18)*1.07,0))) -> 2416 | N4: =IF(((G4*$A$1)*24)<$C$1,"-",IF(ROUNDUP((((G4*100/107)*(1+($A$1*24)))/24)*1.07,0)<$B$1,"-",ROUNDUP(((((G4*100/107)+$D4)*(1+($A$1*24)))/24)*1.07,0))) -> 1916 | O4: =ROUNDUP($B4*20%,0) -> 7998 | P4: =$B4-O4 -> 31992 | Q4: =P4+$D4 -> 33892 | R4: =IF(((P4*$A$1)*6)<$C$1,"-",IF(ROUNDUP((((P4*100/107)*(1+($A$1*6)))/6)*1.07,0)<$B$1,"-",ROUNDUP(((((P4*100/107)+$D4)*(1+($A$1*6)))/6)*1.07,0))) -> 6063 | S4: =IF(((P4*$A$1)*9)<$C$1,"-",IF(ROUNDUP((((P4*100/107)*(1+($A$1*9)))/9)*1.07,0)<$B$1,"-",ROUNDUP(((((P4*100/107)+$D4)*(1+($A$1*9)))/9)*1.07,0))) -> 4172 | T4: =IF(((P4*$A$1)*12)<$C$1,"-",IF(ROUNDUP((((P4*100/107)*(1+($A$1*12)))/12)*1.07,0)<$B$1,"-",ROUNDUP(((((P4*100/107)+$D4)*(1+($A$1*12)))/12)*1.07,0))) -> 3227 | U4: =IF(((P4*$A$1)*15)<$C$1,"-",IF(ROUNDUP((((P4*100/107)*(1+($A$1*15)))/15)*1.07,0)<$B$1,"-",ROUNDUP(((((P4*100/107)+$D4)*(1+($A$1*15)))/15)*1.07,0))) -> 2660 | V4: =IF(((P4*$A$1)*18)<$C$1,"-",IF(ROUNDUP((((P4*100/107)*(1+($A$1*18)))/18)*1.07,0)<$B$1,"-",ROUNDUP(((((P4*100/107)+$D4)*(1+($A$1*18)))/18)*1.07,0))) -> 2282 | W4: =IF(((P4*$A$1)*24)<$C$1,"-",IF(ROUNDUP((((P4*100/107)*(1+($A$1*24)))/24)*1.07,0)<$B$1,"-",ROUNDUP(((((P4*100/107)+$D4)*(1+($A$1*24)))/24)*1.07,0))) -> 1809 | X4: =ROUNDUP($B4*25%,0) -> 9998 | Y4: =$B4-X4 -> 29992 | Z4: =Y4+$D4 -> 31892 | AA4: =IF(((Y4*$A$1)*6)<$C$1,"-",IF(ROUNDUP((((Y4*100/107)*(1+($A$1*6)))/6)*1.07,0)<$B$1,"-",ROUNDUP(((((Y4*100/107)+$D4)*(1+($A$1*6)))/6)*1.07,0))) -> 5706 | AB4: =IF(((Y4*$A$1)*9)<$C$1,"-",IF(ROUNDUP((((Y4*100/107)*(1+($A$1*9)))/9)*1.07,0)<$B$1,"-",ROUNDUP(((((Y4*100/107)+$D4)*(1+($A$1*9)))/9)*1.07,0))) -> 3927 | AC4: =IF(((Y4*$A$1)*12)<$C$1,"-",IF(ROUNDUP((((Y4*100/107)*(1+($A$1*12)))/12)*1.07,0)<$B$1,"-",ROUNDUP(((((Y4*100/107)+$D4)*(1+($A$1*12)))/12)*1.07,0))) -> 3038 | AD4: =IF(((Y4*$A$1)*15)<$C$1,"-",IF(ROUNDUP((((Y4*100/107)*(1+($A$1*15)))/15)*1.07,0)<$B$1,"-",ROUNDUP(((((Y4*100/107)+$D4)*(1+($A$1*15)))/15)*1.07,0))) -> 2504 | AE4: =IF(((Y4*$A$1)*18)<$C$1,"-",IF(ROUNDUP((((Y4*100/107)*(1+($A$1*18)))/18)*1.07,0)<$B$1,"-",ROUNDUP(((((Y4*100/107)+$D4)*(1+($A$1*18)))/18)*1.07,0))) -> 2148 | AF4: =IF(((Y4*$A$1)*24)<$C$1,"-",IF(ROUNDUP((((Y4*100/107)*(1+($A$1*24)))/24)*1.07,0)<$B$1,"-",ROUNDUP(((((Y4*100/107)+$D4)*(1+($A$1*24)))/24)*1.07,0))) -> 1703 | AG4: =ROUNDUP($B4*35%,0) -> 13997 | AH4: =$B4-AG4 -> 25993 | AI4: =AH4+$D4 -> 27893 | AJ4: =IF(((AH4*$A$1)*6)<$C$1,"-",IF(ROUNDUP((((AH4*100/107)*(1+($A$1*6)))/6)*1.07,0)<$B$1,"-",ROUNDUP(((((AH4*100/107)+$D4)*(1+($A$1*6)))/6)*1.07,0))) -> 4994 | AK4: =IF(((AH4*$A$1)*9)<$C$1,"-",IF(ROUNDUP((((AH4*100/107)*(1+($A$1*9)))/9)*1.07,0)<$B$1,"-",ROUNDUP(((((AH4*100/107)+$D4)*(1+($A$1*9)))/9)*1.07,0))) -> 3437 | AL4: =IF(((AH4*$A$1)*12)<$C$1,"-",IF(ROUNDUP((((AH4*100/107)*(1+($A$1*12)))/12)*1.07,0)<$B$1,"-",ROUNDUP(((((AH4*100/107)+$D4)*(1+($A$1*12)))/12)*1.07,0))) -> 2658 | AM4: =IF(((AH4*$A$1)*15)<$C$1,"-",IF(ROUNDUP((((AH4*100/107)*(1+($A$1*15)))/15)*1.07,0)<$B$1,"-",ROUNDUP(((((AH4*100/107)+$D4)*(1+($A$1*15)))/15)*1.07,0))) -> 2191 | AN4: =IF(((AH4*$A$1)*18)<$C$1,"-",IF(ROUNDUP((((AH4*100/107)*(1+($A$1*18)))/18)*1.07,0)<$B$1,"-",ROUNDUP(((((AH4*100/107)+$D4)*(1+($A$1*18)))/18)*1.07,0))) -> 1880 | AO4: =IF(((AH4*$A$1)*24)<$C$1,"-",IF(ROUNDUP((((AH4*100/107)*(1+($A$1*24)))/24)*1.07,0)<$B$1,"-",ROUNDUP(((((AH4*100/107)+$D4)*(1+($A$1*24)))/24)*1.07,0))) -> 1491 | AP4: =ROUNDUP($B4*40%,0) -> 15996 | AQ4: =$B4-AP4 -> 23994 | AR4: =AQ4+$D4 -> 25894 | AS4: =IF(((AQ4*$A$1)*6)<$C$1,"-",IF(ROUNDUP((((AQ4*100/107)*(1+($A$1*6)))/6)*1.07,0)<$B$1,"-",ROUNDUP(((((AQ4*100/107)+$D4)*(1+($A$1*6)))/6)*1.07,0))) -> 4638 | AT4: =IF(((AQ4*$A$1)*9)<$C$1,"-",IF(ROUNDUP((((AQ4*100/107)*(1+($A$1*9)))/9)*1.07,0)<$B$1,"-",ROUNDUP(((((AQ4*100/107)+$D4)*(1+($A$1*9)))/9)*1.07,0))) -> 3192 | AU4: =IF(((AQ4*$A$1)*12)<$C$1,"-",IF(ROUNDUP((((AQ4*100/107)*(1+($A$1*12)))/12)*1.07,0)<$B$1,"-",ROUNDUP(((((AQ4*100/107)+$D4)*(1+($A$1*12)))/12)*1.07,0))) -> 2469 | AV4: =IF(((AQ4*$A$1)*15)<$C$1,"-",IF(ROUNDUP((((AQ4*100/107)*(1+($A$1*15)))/15)*1.07,0)<$B$1,"-",ROUNDUP(((((AQ4*100/107)+$D4)*(1+($A$1*15)))/15)*1.07,0))) -> 2035 | AW4: =IF(((AQ4*$A$1)*18)<$C$1,"-",IF(ROUNDUP((((AQ4*100/107)*(1+($A$1*18)))/18)*1.07,0)<$B$1,"-",ROUNDUP(((((AQ4*100/107)+$D4)*(1+($A$1*18)))/18)*1.07,0))) -> 1746 | AX4: =IF(((AQ4*$A$1)*24)<$C$1,"-",IF(ROUNDUP((((AQ4*100/107)*(1+($A$1*24)))/24)*1.07,0)<$B$1,"-",ROUNDUP(((((AQ4*100/107)+$D4)*(1+($A$1*24)))/24)*1.07,0))) -> 1384
A5: {=IFERROR(INDEX('Product Price'!A:A,SMALL('Product Price'!$D:$D,3)),"")} -> HONOR X6d 4/128 GB | B5: {=IFERROR(INDEX('Product Price'!B:B,SMALL('Product Price'!$D:$D,3)),"")} -> 5999 | C5: {=IFERROR(INDEX('Product Price'!C:C,SMALL('Product Price'!$D:$D,3)),"")} -> 2 | D5: =IF(AND(B5>=3900,B5<=10000),795,IF(AND(B5>=10001,B5<=20000),1450,IF(AND(B5>=20001,B5<=40000),1900,IF(AND(B5>=40001,B5<=60000),2475,IF(AND(B5>=60001,B5<=80000),4025,IF(AND(B5>=80001,B5<=100000),5175,IF(AND(B5>=100001,B5<=120000),6785,""))))))) -> 795 | E5: =IFERROR(B5+D5,"") -> 6794 | F5: =IFERROR(ROUNDUP($B5*15%,0),"") -> 900 | G5: =$B5-F5 -> 5099 | H5: =$G5+D5 -> 5894 | I5: =IF(((G5*$A$1)*6)<$C$1,"-",IF(ROUNDUP((((G5*100/107)*(1+($A$1*6)))/6)*1.07,0)<$B$1,"-",ROUNDUP(((((G5*100/107)+$D5)*(1+($A$1*6)))/6)*1.07,0))) -> 1061 | J5: =IF(((G5*$A$1)*9)<$C$1,"-",IF(ROUNDUP((((G5*100/107)*(1+($A$1*9)))/9)*1.07,0)<$B$1,"-",ROUNDUP(((((G5*100/107)+$D5)*(1+($A$1*9)))/9)*1.07,0))) -> 730 | K5: =IF(((G5*$A$1)*12)<$C$1,"-",IF(ROUNDUP((((G5*100/107)*(1+($A$1*12)))/12)*1.07,0)<$B$1,"-",ROUNDUP(((((G5*100/107)+$D5)*(1+($A$1*12)))/12)*1.07,0))) -> 565 | L5: =IF(((G5*$A$1)*15)<$C$1,"-",IF(ROUNDUP((((G5*100/107)*(1+($A$1*15)))/15)*1.07,0)<$B$1,"-",ROUNDUP(((((G5*100/107)+$D5)*(1+($A$1*15)))/15)*1.07,0))) -> - | M5: =IF(((G5*$A$1)*18)<$C$1,"-",IF(ROUNDUP((((G5*100/107)*(1+($A$1*18)))/18)*1.07,0)<$B$1,"-",ROUNDUP(((((G5*100/107)+$D5)*(1+($A$1*18)))/18)*1.07,0))) -> - | N5: =IF(((G5*$A$1)*24)<$C$1,"-",IF(ROUNDUP((((G5*100/107)*(1+($A$1*24)))/24)*1.07,0)<$B$1,"-",ROUNDUP(((((G5*100/107)+$D5)*(1+($A$1*24)))/24)*1.07,0))) -> - | O5: =ROUNDUP($B5*20%,0) -> 1200 | P5: =$B5-O5 -> 4799 | Q5: =P5+$D5 -> 5594 | R5: =IF(((P5*$A$1)*6)<$C$1,"-",IF(ROUNDUP((((P5*100/107)*(1+($A$1*6)))/6)*1.07,0)<$B$1,"-",ROUNDUP(((((P5*100/107)+$D5)*(1+($A$1*6)))/6)*1.07,0))) -> 1007 | S5: =IF(((P5*$A$1)*9)<$C$1,"-",IF(ROUNDUP((((P5*100/107)*(1+($A$1*9)))/9)*1.07,0)<$B$1,"-",ROUNDUP(((((P5*100/107)+$D5)*(1+($A$1*9)))/9)*1.07,0))) -> 693 | T5: =IF(((P5*$A$1)*12)<$C$1,"-",IF(ROUNDUP((((P5*100/107)*(1+($A$1*12)))/12)*1.07,0)<$B$1,"-",ROUNDUP(((((P5*100/107)+$D5)*(1+($A$1*12)))/12)*1.07,0))) -> 536 | U5: =IF(((P5*$A$1)*15)<$C$1,"-",IF(ROUNDUP((((P5*100/107)*(1+($A$1*15)))/15)*1.07,0)<$B$1,"-",ROUNDUP(((((P5*100/107)+$D5)*(1+($A$1*15)))/15)*1.07,0))) -> - | V5: =IF(((P5*$A$1)*18)<$C$1,"-",IF(ROUNDUP((((P5*100/107)*(1+($A$1*18)))/18)*1.07,0)<$B$1,"-",ROUNDUP(((((P5*100/107)+$D5)*(1+($A$1*18)))/18)*1.07,0))) -> - | W5: =IF(((P5*$A$1)*24)<$C$1,"-",IF(ROUNDUP((((P5*100/107)*(1+($A$1*24)))/24)*1.07,0)<$B$1,"-",ROUNDUP(((((P5*100/107)+$D5)*(1+($A$1*24)))/24)*1.07,0))) -> - | X5: =ROUNDUP($B5*25%,0) -> 1500 | Y5: =$B5-X5 -> 4499 | Z5: =Y5+$D5 -> 5294 | AA5: =IF(((Y5*$A$1)*6)<$C$1,"-",IF(ROUNDUP((((Y5*100/107)*(1+($A$1*6)))/6)*1.07,0)<$B$1,"-",ROUNDUP(((((Y5*100/107)+$D5)*(1+($A$1*6)))/6)*1.07,0))) -> 954 | AB5: =IF(((Y5*$A$1)*9)<$C$1,"-",IF(ROUNDUP((((Y5*100/107)*(1+($A$1*9)))/9)*1.07,0)<$B$1,"-",ROUNDUP(((((Y5*100/107)+$D5)*(1+($A$1*9)))/9)*1.07,0))) -> 656 | AC5: =IF(((Y5*$A$1)*12)<$C$1,"-",IF(ROUNDUP((((Y5*100/107)*(1+($A$1*12)))/12)*1.07,0)<$B$1,"-",ROUNDUP(((((Y5*100/107)+$D5)*(1+($A$1*12)))/12)*1.07,0))) -> 508 | AD5: =IF(((Y5*$A$1)*15)<$C$1,"-",IF(ROUNDUP((((Y5*100/107)*(1+($A$1*15)))/15)*1.07,0)<$B$1,"-",ROUNDUP(((((Y5*100/107)+$D5)*(1+($A$1*15)))/15)*1.07,0))) -> - | AE5: =IF(((Y5*$A$1)*18)<$C$1,"-",IF(ROUNDUP((((Y5*100/107)*(1+($A$1*18)))/18)*1.07,0)<$B$1,"-",ROUNDUP(((((Y5*100/107)+$D5)*(1+($A$1*18)))/18)*1.07,0))) -> - | AF5: =IF(((Y5*$A$1)*24)<$C$1,"-",IF(ROUNDUP((((Y5*100/107)*(1+($A$1*24)))/24)*1.07,0)<$B$1,"-",ROUNDUP(((((Y5*100/107)+$D5)*(1+($A$1*24)))/24)*1.07,0))) -> - | AG5: =ROUNDUP($B5*35%,0) -> 2100 | AH5: =$B5-AG5 -> 3899 | AI5: =AH5+$D5 -> 4694 | AJ5: =IF(((AH5*$A$1)*6)<$C$1,"-",IF(ROUNDUP((((AH5*100/107)*(1+($A$1*6)))/6)*1.07,0)<$B$1,"-",ROUNDUP(((((AH5*100/107)+$D5)*(1+($A$1*6)))/6)*1.07,0))) -> 847 | AK5: =IF(((AH5*$A$1)*9)<$C$1,"-",IF(ROUNDUP((((AH5*100/107)*(1+($A$1*9)))/9)*1.07,0)<$B$1,"-",ROUNDUP(((((AH5*100/107)+$D5)*(1+($A$1*9)))/9)*1.07,0))) -> 583 | AL5: =IF(((AH5*$A$1)*12)<$C$1,"-",IF(ROUNDUP((((AH5*100/107)*(1+($A$1*12)))/12)*1.07,0)<$B$1,"-",ROUNDUP(((((AH5*100/107)+$D5)*(1+($A$1*12)))/12)*1.07,0))) -> - | AM5: =IF(((AH5*$A$1)*15)<$C$1,"-",IF(ROUNDUP((((AH5*100/107)*(1+($A$1*15)))/15)*1.07,0)<$B$1,"-",ROUNDUP(((((AH5*100/107)+$D5)*(1+($A$1*15)))/15)*1.07,0))) -> - | AN5: =IF(((AH5*$A$1)*18)<$C$1,"-",IF(ROUNDUP((((AH5*100/107)*(1+($A$1*18)))/18)*1.07,0)<$B$1,"-",ROUNDUP(((((AH5*100/107)+$D5)*(1+($A$1*18)))/18)*1.07,0))) -> - | AO5: =IF(((AH5*$A$1)*24)<$C$1,"-",IF(ROUNDUP((((AH5*100/107)*(1+($A$1*24)))/24)*1.07,0)<$B$1,"-",ROUNDUP(((((AH5*100/107)+$D5)*(1+($A$1*24)))/24)*1.07,0))) -> - | AP5: =ROUNDUP($B5*40%,0) -> 2400 | AQ5: =$B5-AP5 -> 3599 | AR5: =AQ5+$D5 -> 4394 | AS5: =IF(((AQ5*$A$1)*6)<$C$1,"-",IF(ROUNDUP((((AQ5*100/107)*(1+($A$1*6)))/6)*1.07,0)<$B$1,"-",ROUNDUP(((((AQ5*100/107)+$D5)*(1+($A$1*6)))/6)*1.07,0))) -> 793 | AT5: =IF(((AQ5*$A$1)*9)<$C$1,"-",IF(ROUNDUP((((AQ5*100/107)*(1+($A$1*9)))/9)*1.07,0)<$B$1,"-",ROUNDUP(((((AQ5*100/107)+$D5)*(1+($A$1*9)))/9)*1.07,0))) -> 546 | AU5: =IF(((AQ5*$A$1)*12)<$C$1,"-",IF(ROUNDUP((((AQ5*100/107)*(1+($A$1*12)))/12)*1.07,0)<$B$1,"-",ROUNDUP(((((AQ5*100/107)+$D5)*(1+($A$1*12)))/12)*1.07,0))) -> - | AV5: =IF(((AQ5*$A$1)*15)<$C$1,"-",IF(ROUNDUP((((AQ5*100/107)*(1+($A$1*15)))/15)*1.07,0)<$B$1,"-",ROUNDUP(((((AQ5*100/107)+$D5)*(1+($A$1*15)))/15)*1.07,0))) -> - | AW5: =IF(((AQ5*$A$1)*18)<$C$1,"-",IF(ROUNDUP((((AQ5*100/107)*(1+($A$1*18)))/18)*1.07,0)<$B$1,"-",ROUNDUP(((((AQ5*100/107)+$D5)*(1+($A$1*18)))/18)*1.07,0))) -> - | AX5: =IF(((AQ5*$A$1)*24)<$C$1,"-",IF(ROUNDUP((((AQ5*100/107)*(1+($A$1*24)))/24)*1.07,0)<$B$1,"-",ROUNDUP(((((AQ5*100/107)+$D5)*(1+($A$1*24)))/24)*1.07,0))) -> -
A6: {=IFERROR(INDEX('Product Price'!A:A,SMALL('Product Price'!$D:$D,4)),"")} -> HONOR 600 Lite 5G 8/256 GB | B6: {=IFERROR(INDEX('Product Price'!B:B,SMALL('Product Price'!$D:$D,4)),"")} -> 13999 | C6: {=IFERROR(INDEX('Product Price'!C:C,SMALL('Product Price'!$D:$D,4)),"")} -> 3 | D6: =IF(AND(B6>=3900,B6<=10000),795,IF(AND(B6>=10001,B6<=20000),1450,IF(AND(B6>=20001,B6<=40000),1900,IF(AND(B6>=40001,B6<=60000),2475,IF(AND(B6>=60001,B6<=80000),4025,IF(AND(B6>=80001,B6<=100000),5175,IF(AND(B6>=100001,B6<=120000),6785,""))))))) -> 1450 | E6: =IFERROR(B6+D6,"") -> 15449 | F6: =IFERROR(ROUNDUP($B6*15%,0),"") -> 2100 | G6: =$B6-F6 -> 11899 | H6: =$G6+D6 -> 13349 | I6: =IF(((G6*$A$1)*6)<$C$1,"-",IF(ROUNDUP((((G6*100/107)*(1+($A$1*6)))/6)*1.07,0)<$B$1,"-",ROUNDUP(((((G6*100/107)+$D6)*(1+($A$1*6)))/6)*1.07,0))) -> 2397 | J6: =IF(((G6*$A$1)*9)<$C$1,"-",IF(ROUNDUP((((G6*100/107)*(1+($A$1*9)))/9)*1.07,0)<$B$1,"-",ROUNDUP(((((G6*100/107)+$D6)*(1+($A$1*9)))/9)*1.07,0))) -> 1650 | K6: =IF(((G6*$A$1)*12)<$C$1,"-",IF(ROUNDUP((((G6*100/107)*(1+($A$1*12)))/12)*1.07,0)<$B$1,"-",ROUNDUP(((((G6*100/107)+$D6)*(1+($A$1*12)))/12)*1.07,0))) -> 1276 | L6: =IF(((G6*$A$1)*15)<$C$1,"-",IF(ROUNDUP((((G6*100/107)*(1+($A$1*15)))/15)*1.07,0)<$B$1,"-",ROUNDUP(((((G6*100/107)+$D6)*(1+($A$1*15)))/15)*1.07,0))) -> 1052 | M6: =IF(((G6*$A$1)*18)<$C$1,"-",IF(ROUNDUP((((G6*100/107)*(1+($A$1*18)))/18)*1.07,0)<$B$1,"-",ROUNDUP(((((G6*100/107)+$D6)*(1+($A$1*18)))/18)*1.07,0))) -> 902 | N6: =IF(((G6*$A$1)*24)<$C$1,"-",IF(ROUNDUP((((G6*100/107)*(1+($A$1*24)))/24)*1.07,0)<$B$1,"-",ROUNDUP(((((G6*100/107)+$D6)*(1+($A$1*24)))/24)*1.07,0))) -> 716 | O6: =ROUNDUP($B6*20%,0) -> 2800 | P6: =$B6-O6 -> 11199 | Q6: =P6+$D6 -> 12649 | R6: =IF(((P6*$A$1)*6)<$C$1,"-",IF(ROUNDUP((((P6*100/107)*(1+($A$1*6)))/6)*1.07,0)<$B$1,"-",ROUNDUP(((((P6*100/107)+$D6)*(1+($A$1*6)))/6)*1.07,0))) -> 2272 | S6: =IF(((P6*$A$1)*9)<$C$1,"-",IF(ROUNDUP((((P6*100/107)*(1+($A$1*9)))/9)*1.07,0)<$B$1,"-",ROUNDUP(((((P6*100/107)+$D6)*(1+($A$1*9)))/9)*1.07,0))) -> 1564 | T6: =IF(((P6*$A$1)*12)<$C$1,"-",IF(ROUNDUP((((P6*100/107)*(1+($A$1*12)))/12)*1.07,0)<$B$1,"-",ROUNDUP(((((P6*100/107)+$D6)*(1+($A$1*12)))/12)*1.07,0))) -> 1210 | U6: =IF(((P6*$A$1)*15)<$C$1,"-",IF(ROUNDUP((((P6*100/107)*(1+($A$1*15)))/15)*1.07,0)<$B$1,"-",ROUNDUP(((((P6*100/107)+$D6)*(1+($A$1*15)))/15)*1.07,0))) -> 997 | V6: =IF(((P6*$A$1)*18)<$C$1,"-",IF(ROUNDUP((((P6*100/107)*(1+($A$1*18)))/18)*1.07,0)<$B$1,"-",ROUNDUP(((((P6*100/107)+$D6)*(1+($A$1*18)))/18)*1.07,0))) -> 855 | W6: =IF(((P6*$A$1)*24)<$C$1,"-",IF(ROUNDUP((((P6*100/107)*(1+($A$1*24)))/24)*1.07,0)<$B$1,"-",ROUNDUP(((((P6*100/107)+$D6)*(1+($A$1*24)))/24)*1.07,0))) -> 678 | X6: =ROUNDUP($B6*25%,0) -> 3500 | Y6: =$B6-X6 -> 10499 | Z6: =Y6+$D6 -> 11949 | AA6: =IF(((Y6*$A$1)*6)<$C$1,"-",IF(ROUNDUP((((Y6*100/107)*(1+($A$1*6)))/6)*1.07,0)<$B$1,"-",ROUNDUP(((((Y6*100/107)+$D6)*(1+($A$1*6)))/6)*1.07,0))) -> 2147 | AB6: =IF(((Y6*$A$1)*9)<$C$1,"-",IF(ROUNDUP((((Y6*100/107)*(1+($A$1*9)))/9)*1.07,0)<$B$1,"-",ROUNDUP(((((Y6*100/107)+$D6)*(1+($A$1*9)))/9)*1.07,0))) -> 1478 | AC6: =IF(((Y6*$A$1)*12)<$C$1,"-",IF(ROUNDUP((((Y6*100/107)*(1+($A$1*12)))/12)*1.07,0)<$B$1,"-",ROUNDUP(((((Y6*100/107)+$D6)*(1+($A$1*12)))/12)*1.07,0))) -> 1143 | AD6: =IF(((Y6*$A$1)*15)<$C$1,"-",IF(ROUNDUP((((Y6*100/107)*(1+($A$1*15)))/15)*1.07,0)<$B$1,"-",ROUNDUP(((((Y6*100/107)+$D6)*(1+($A$1*15)))/15)*1.07,0))) -> 942 | AE6: =IF(((Y6*$A$1)*18)<$C$1,"-",IF(ROUNDUP((((Y6*100/107)*(1+($A$1*18)))/18)*1.07,0)<$B$1,"-",ROUNDUP(((((Y6*100/107)+$D6)*(1+($A$1*18)))/18)*1.07,0))) -> 809 | AF6: =IF(((Y6*$A$1)*24)<$C$1,"-",IF(ROUNDUP((((Y6*100/107)*(1+($A$1*24)))/24)*1.07,0)<$B$1,"-",ROUNDUP(((((Y6*100/107)+$D6)*(1+($A$1*24)))/24)*1.07,0))) -> 641 | AG6: =ROUNDUP($B6*35%,0) -> 4900 | AH6: =$B6-AG6 -> 9099 | AI6: =AH6+$D6 -> 10549 | AJ6: =IF(((AH6*$A$1)*6)<$C$1,"-",IF(ROUNDUP((((AH6*100/107)*(1+($A$1*6)))/6)*1.07,0)<$B$1,"-",ROUNDUP(((((AH6*100/107)+$D6)*(1+($A$1*6)))/6)*1.07,0))) -> 1898 | AK6: =IF(((AH6*$A$1)*9)<$C$1,"-",IF(ROUNDUP((((AH6*100/107)*(1+($A$1*9)))/9)*1.07,0)<$B$1,"-",ROUNDUP(((((AH6*100/107)+$D6)*(1+($A$1*9)))/9)*1.07,0))) -> 1306 | AL6: =IF(((AH6*$A$1)*12)<$C$1,"-",IF(ROUNDUP((((AH6*100/107)*(1+($A$1*12)))/12)*1.07,0)<$B$1,"-",ROUNDUP(((((AH6*100/107)+$D6)*(1+($A$1*12)))/12)*1.07,0))) -> 1011 | AM6: =IF(((AH6*$A$1)*15)<$C$1,"-",IF(ROUNDUP((((AH6*100/107)*(1+($A$1*15)))/15)*1.07,0)<$B$1,"-",ROUNDUP(((((AH6*100/107)+$D6)*(1+($A$1*15)))/15)*1.07,0))) -> 833 | AN6: =IF(((AH6*$A$1)*18)<$C$1,"-",IF(ROUNDUP((((AH6*100/107)*(1+($A$1*18)))/18)*1.07,0)<$B$1,"-",ROUNDUP(((((AH6*100/107)+$D6)*(1+($A$1*18)))/18)*1.07,0))) -> 715 | AO6: =IF(((AH6*$A$1)*24)<$C$1,"-",IF(ROUNDUP((((AH6*100/107)*(1+($A$1*24)))/24)*1.07,0)<$B$1,"-",ROUNDUP(((((AH6*100/107)+$D6)*(1+($A$1*24)))/24)*1.07,0))) -> 567 | AP6: =ROUNDUP($B6*40%,0) -> 5600 | AQ6: =$B6-AP6 -> 8399 | AR6: =AQ6+$D6 -> 9849 | AS6: =IF(((AQ6*$A$1)*6)<$C$1,"-",IF(ROUNDUP((((AQ6*100/107)*(1+($A$1*6)))/6)*1.07,0)<$B$1,"-",ROUNDUP(((((AQ6*100/107)+$D6)*(1+($A$1*6)))/6)*1.07,0))) -> 1773 | AT6: =IF(((AQ6*$A$1)*9)<$C$1,"-",IF(ROUNDUP((((AQ6*100/107)*(1+($A$1*9)))/9)*1.07,0)<$B$1,"-",ROUNDUP(((((AQ6*100/107)+$D6)*(1+($A$1*9)))/9)*1.07,0))) -> 1221 | AU6: =IF(((AQ6*$A$1)*12)<$C$1,"-",IF(ROUNDUP((((AQ6*100/107)*(1+($A$1*12)))/12)*1.07,0)<$B$1,"-",ROUNDUP(((((AQ6*100/107)+$D6)*(1+($A$1*12)))/12)*1.07,0))) -> 944 | AV6: =IF(((AQ6*$A$1)*15)<$C$1,"-",IF(ROUNDUP((((AQ6*100/107)*(1+($A$1*15)))/15)*1.07,0)<$B$1,"-",ROUNDUP(((((AQ6*100/107)+$D6)*(1+($A$1*15)))/15)*1.07,0))) -> 778 | AW6: =IF(((AQ6*$A$1)*18)<$C$1,"-",IF(ROUNDUP((((AQ6*100/107)*(1+($A$1*18)))/18)*1.07,0)<$B$1,"-",ROUNDUP(((((AQ6*100/107)+$D6)*(1+($A$1*18)))/18)*1.07,0))) -> 668 | AX6: =IF(((AQ6*$A$1)*24)<$C$1,"-",IF(ROUNDUP((((AQ6*100/107)*(1+($A$1*24)))/24)*1.07,0)<$B$1,"-",ROUNDUP(((((AQ6*100/107)+$D6)*(1+($A$1*24)))/24)*1.07,0))) -> 530
A7: {=IFERROR(INDEX('Product Price'!A:A,SMALL('Product Price'!$D:$D,5)),"")} -> HONOR 600 5G 12/256 GB | B7: {=IFERROR(INDEX('Product Price'!B:B,SMALL('Product Price'!$D:$D,5)),"")} -> 19999 | C7: {=IFERROR(INDEX('Product Price'!C:C,SMALL('Product Price'!$D:$D,5)),"")} -> 4 | D7: =IF(AND(B7>=3900,B7<=10000),795,IF(AND(B7>=10001,B7<=20000),1450,IF(AND(B7>=20001,B7<=40000),1900,IF(AND(B7>=40001,B7<=60000),2475,IF(AND(B7>=60001,B7<=80000),4025,IF(AND(B7>=80001,B7<=100000),5175,IF(AND(B7>=100001,B7<=120000),6785,""))))))) -> 1450 | E7: =IFERROR(B7+D7,"") -> 21449 | F7: =IFERROR(ROUNDUP($B7*15%,0),"") -> 3000 | G7: =$B7-F7 -> 16999 | H7: =$G7+D7 -> 18449 | I7: =IF(((G7*$A$1)*6)<$C$1,"-",IF(ROUNDUP((((G7*100/107)*(1+($A$1*6)))/6)*1.07,0)<$B$1,"-",ROUNDUP(((((G7*100/107)+$D7)*(1+($A$1*6)))/6)*1.07,0))) -> 3306 | J7: =IF(((G7*$A$1)*9)<$C$1,"-",IF(ROUNDUP((((G7*100/107)*(1+($A$1*9)))/9)*1.07,0)<$B$1,"-",ROUNDUP(((((G7*100/107)+$D7)*(1+($A$1*9)))/9)*1.07,0))) -> 2275 | K7: =IF(((G7*$A$1)*12)<$C$1,"-",IF(ROUNDUP((((G7*100/107)*(1+($A$1*12)))/12)*1.07,0)<$B$1,"-",ROUNDUP(((((G7*100/107)+$D7)*(1+($A$1*12)))/12)*1.07,0))) -> 1760 | L7: =IF(((G7*$A$1)*15)<$C$1,"-",IF(ROUNDUP((((G7*100/107)*(1+($A$1*15)))/15)*1.07,0)<$B$1,"-",ROUNDUP(((((G7*100/107)+$D7)*(1+($A$1*15)))/15)*1.07,0))) -> 1451 | M7: =IF(((G7*$A$1)*18)<$C$1,"-",IF(ROUNDUP((((G7*100/107)*(1+($A$1*18)))/18)*1.07,0)<$B$1,"-",ROUNDUP(((((G7*100/107)+$D7)*(1+($A$1*18)))/18)*1.07,0))) -> 1244 | N7: =IF(((G7*$A$1)*24)<$C$1,"-",IF(ROUNDUP((((G7*100/107)*(1+($A$1*24)))/24)*1.07,0)<$B$1,"-",ROUNDUP(((((G7*100/107)+$D7)*(1+($A$1*24)))/24)*1.07,0))) -> 987 | O7: =ROUNDUP($B7*20%,0) -> 4000 | P7: =$B7-O7 -> 15999 | Q7: =P7+$D7 -> 17449 | R7: =IF(((P7*$A$1)*6)<$C$1,"-",IF(ROUNDUP((((P7*100/107)*(1+($A$1*6)))/6)*1.07,0)<$B$1,"-",ROUNDUP(((((P7*100/107)+$D7)*(1+($A$1*6)))/6)*1.07,0))) -> 3127 | S7: =IF(((P7*$A$1)*9)<$C$1,"-",IF(ROUNDUP((((P7*100/107)*(1+($A$1*9)))/9)*1.07,0)<$B$1,"-",ROUNDUP(((((P7*100/107)+$D7)*(1+($A$1*9)))/9)*1.07,0))) -> 2152 | T7: =IF(((P7*$A$1)*12)<$C$1,"-",IF(ROUNDUP((((P7*100/107)*(1+($A$1*12)))/12)*1.07,0)<$B$1,"-",ROUNDUP(((((P7*100/107)+$D7)*(1+($A$1*12)))/12)*1.07,0))) -> 1665 | U7: =IF(((P7*$A$1)*15)<$C$1,"-",IF(ROUNDUP((((P7*100/107)*(1+($A$1*15)))/15)*1.07,0)<$B$1,"-",ROUNDUP(((((P7*100/107)+$D7)*(1+($A$1*15)))/15)*1.07,0))) -> 1372 | V7: =IF(((P7*$A$1)*18)<$C$1,"-",IF(ROUNDUP((((P7*100/107)*(1+($A$1*18)))/18)*1.07,0)<$B$1,"-",ROUNDUP(((((P7*100/107)+$D7)*(1+($A$1*18)))/18)*1.07,0))) -> 1177 | W7: =IF(((P7*$A$1)*24)<$C$1,"-",IF(ROUNDUP((((P7*100/107)*(1+($A$1*24)))/24)*1.07,0)<$B$1,"-",ROUNDUP(((((P7*100/107)+$D7)*(1+($A$1*24)))/24)*1.07,0))) -> 934 | X7: =ROUNDUP($B7*25%,0) -> 5000 | Y7: =$B7-X7 -> 14999 | Z7: =Y7+$D7 -> 16449 | AA7: =IF(((Y7*$A$1)*6)<$C$1,"-",IF(ROUNDUP((((Y7*100/107)*(1+($A$1*6)))/6)*1.07,0)<$B$1,"-",ROUNDUP(((((Y7*100/107)+$D7)*(1+($A$1*6)))/6)*1.07,0))) -> 2949 | AB7: =IF(((Y7*$A$1)*9)<$C$1,"-",IF(ROUNDUP((((Y7*100/107)*(1+($A$1*9)))/9)*1.07,0)<$B$1,"-",ROUNDUP(((((Y7*100/107)+$D7)*(1+($A$1*9)))/9)*1.07,0))) -> 2030 | AC7: =IF(((Y7*$A$1)*12)<$C$1,"-",IF(ROUNDUP((((Y7*100/107)*(1+($A$1*12)))/12)*1.07,0)<$B$1,"-",ROUNDUP(((((Y7*100/107)+$D7)*(1+($A$1*12)))/12)*1.07,0))) -> 1570 | AD7: =IF(((Y7*$A$1)*15)<$C$1,"-",IF(ROUNDUP((((Y7*100/107)*(1+($A$1*15)))/15)*1.07,0)<$B$1,"-",ROUNDUP(((((Y7*100/107)+$D7)*(1+($A$1*15)))/15)*1.07,0))) -> 1294 | AE7: =IF(((Y7*$A$1)*18)<$C$1,"-",IF(ROUNDUP((((Y7*100/107)*(1+($A$1*18)))/18)*1.07,0)<$B$1,"-",ROUNDUP(((((Y7*100/107)+$D7)*(1+($A$1*18)))/18)*1.07,0))) -> 1110 | AF7: =IF(((Y7*$A$1)*24)<$C$1,"-",IF(ROUNDUP((((Y7*100/107)*(1+($A$1*24)))/24)*1.07,0)<$B$1,"-",ROUNDUP(((((Y7*100/107)+$D7)*(1+($A$1*24)))/24)*1.07,0))) -> 880 | AG7: =ROUNDUP($B7*35%,0) -> 7000 | AH7: =$B7-AG7 -> 12999 | AI7: =AH7+$D7 -> 14449 | AJ7: =IF(((AH7*$A$1)*6)<$C$1,"-",IF(ROUNDUP((((AH7*100/107)*(1+($A$1*6)))/6)*1.07,0)<$B$1,"-",ROUNDUP(((((AH7*100/107)+$D7)*(1+($A$1*6)))/6)*1.07,0))) -> 2593 | AK7: =IF(((AH7*$A$1)*9)<$C$1,"-",IF(ROUNDUP((((AH7*100/107)*(1+($A$1*9)))/9)*1.07,0)<$B$1,"-",ROUNDUP(((((AH7*100/107)+$D7)*(1+($A$1*9)))/9)*1.07,0))) -> 1785 | AL7: =IF(((AH7*$A$1)*12)<$C$1,"-",IF(ROUNDUP((((AH7*100/107)*(1+($A$1*12)))/12)*1.07,0)<$B$1,"-",ROUNDUP(((((AH7*100/107)+$D7)*(1+($A$1*12)))/12)*1.07,0))) -> 1380 | AM7: =IF(((AH7*$A$1)*15)<$C$1,"-",IF(ROUNDUP((((AH7*100/107)*(1+($A$1*15)))/15)*1.07,0)<$B$1,"-",ROUNDUP(((((AH7*100/107)+$D7)*(1+($A$1*15)))/15)*1.07,0))) -> 1138 | AN7: =IF(((AH7*$A$1)*18)<$C$1,"-",IF(ROUNDUP((((AH7*100/107)*(1+($A$1*18)))/18)*1.07,0)<$B$1,"-",ROUNDUP(((((AH7*100/107)+$D7)*(1+($A$1*18)))/18)*1.07,0))) -> 976 | AO7: =IF(((AH7*$A$1)*24)<$C$1,"-",IF(ROUNDUP((((AH7*100/107)*(1+($A$1*24)))/24)*1.07,0)<$B$1,"-",ROUNDUP(((((AH7*100/107)+$D7)*(1+($A$1*24)))/24)*1.07,0))) -> 774 | AP7: =ROUNDUP($B7*40%,0) -> 8000 | AQ7: =$B7-AP7 -> 11999 | AR7: =AQ7+$D7 -> 13449 | AS7: =IF(((AQ7*$A$1)*6)<$C$1,"-",IF(ROUNDUP((((AQ7*100/107)*(1+($A$1*6)))/6)*1.07,0)<$B$1,"-",ROUNDUP(((((AQ7*100/107)+$D7)*(1+($A$1*6)))/6)*1.07,0))) -> 2415 | AT7: =IF(((AQ7*$A$1)*9)<$C$1,"-",IF(ROUNDUP((((AQ7*100/107)*(1+($A$1*9)))/9)*1.07,0)<$B$1,"-",ROUNDUP(((((AQ7*100/107)+$D7)*(1+($A$1*9)))/9)*1.07,0))) -> 1662 | AU7: =IF(((AQ7*$A$1)*12)<$C$1,"-",IF(ROUNDUP((((AQ7*100/107)*(1+($A$1*12)))/12)*1.07,0)<$B$1,"-",ROUNDUP(((((AQ7*100/107)+$D7)*(1+($A$1*12)))/12)*1.07,0))) -> 1286 | AV7: =IF(((AQ7*$A$1)*15)<$C$1,"-",IF(ROUNDUP((((AQ7*100/107)*(1+($A$1*15)))/15)*1.07,0)<$B$1,"-",ROUNDUP(((((AQ7*100/107)+$D7)*(1+($A$1*15)))/15)*1.07,0))) -> 1060 | AW7: =IF(((AQ7*$A$1)*18)<$C$1,"-",IF(ROUNDUP((((AQ7*100/107)*(1+($A$1*18)))/18)*1.07,0)<$B$1,"-",ROUNDUP(((((AQ7*100/107)+$D7)*(1+($A$1*18)))/18)*1.07,0))) -> 909 | AX7: =IF(((AQ7*$A$1)*24)<$C$1,"-",IF(ROUNDUP((((AQ7*100/107)*(1+($A$1*24)))/24)*1.07,0)<$B$1,"-",ROUNDUP(((((AQ7*100/107)+$D7)*(1+($A$1*24)))/24)*1.07,0))) -> 721
A8: {=IFERROR(INDEX('Product Price'!A:A,SMALL('Product Price'!$D:$D,6)),"")} -> HONOR 600 Pro 5G 12/512 GB | B8: {=IFERROR(INDEX('Product Price'!B:B,SMALL('Product Price'!$D:$D,6)),"")} -> 29999 | C8: {=IFERROR(INDEX('Product Price'!C:C,SMALL('Product Price'!$D:$D,6)),"")} -> 5 | D8: =IF(AND(B8>=3900,B8<=10000),795,IF(AND(B8>=10001,B8<=20000),1450,IF(AND(B8>=20001,B8<=40000),1900,IF(AND(B8>=40001,B8<=60000),2475,IF(AND(B8>=60001,B8<=80000),4025,IF(AND(B8>=80001,B8<=100000),5175,IF(AND(B8>=100001,B8<=120000),6785,""))))))) -> 1900 | E8: =IFERROR(B8+D8,"") -> 31899 | F8: =IFERROR(ROUNDUP($B8*15%,0),"") -> 4500 | G8: =$B8-F8 -> 25499 | H8: =$G8+D8 -> 27399 | I8: =IF(((G8*$A$1)*6)<$C$1,"-",IF(ROUNDUP((((G8*100/107)*(1+($A$1*6)))/6)*1.07,0)<$B$1,"-",ROUNDUP(((((G8*100/107)+$D8)*(1+($A$1*6)))/6)*1.07,0))) -> 4906 | J8: =IF(((G8*$A$1)*9)<$C$1,"-",IF(ROUNDUP((((G8*100/107)*(1+($A$1*9)))/9)*1.07,0)<$B$1,"-",ROUNDUP(((((G8*100/107)+$D8)*(1+($A$1*9)))/9)*1.07,0))) -> 3376 | K8: =IF(((G8*$A$1)*12)<$C$1,"-",IF(ROUNDUP((((G8*100/107)*(1+($A$1*12)))/12)*1.07,0)<$B$1,"-",ROUNDUP(((((G8*100/107)+$D8)*(1+($A$1*12)))/12)*1.07,0))) -> 2611 | L8: =IF(((G8*$A$1)*15)<$C$1,"-",IF(ROUNDUP((((G8*100/107)*(1+($A$1*15)))/15)*1.07,0)<$B$1,"-",ROUNDUP(((((G8*100/107)+$D8)*(1+($A$1*15)))/15)*1.07,0))) -> 2153 | M8: =IF(((G8*$A$1)*18)<$C$1,"-",IF(ROUNDUP((((G8*100/107)*(1+($A$1*18)))/18)*1.07,0)<$B$1,"-",ROUNDUP(((((G8*100/107)+$D8)*(1+($A$1*18)))/18)*1.07,0))) -> 1847 | N8: =IF(((G8*$A$1)*24)<$C$1,"-",IF(ROUNDUP((((G8*100/107)*(1+($A$1*24)))/24)*1.07,0)<$B$1,"-",ROUNDUP(((((G8*100/107)+$D8)*(1+($A$1*24)))/24)*1.07,0))) -> 1464 | O8: =ROUNDUP($B8*20%,0) -> 6000 | P8: =$B8-O8 -> 23999 | Q8: =P8+$D8 -> 25899 | R8: =IF(((P8*$A$1)*6)<$C$1,"-",IF(ROUNDUP((((P8*100/107)*(1+($A$1*6)))/6)*1.07,0)<$B$1,"-",ROUNDUP(((((P8*100/107)+$D8)*(1+($A$1*6)))/6)*1.07,0))) -> 4639 | S8: =IF(((P8*$A$1)*9)<$C$1,"-",IF(ROUNDUP((((P8*100/107)*(1+($A$1*9)))/9)*1.07,0)<$B$1,"-",ROUNDUP(((((P8*100/107)+$D8)*(1+($A$1*9)))/9)*1.07,0))) -> 3192 | T8: =IF(((P8*$A$1)*12)<$C$1,"-",IF(ROUNDUP((((P8*100/107)*(1+($A$1*12)))/12)*1.07,0)<$B$1,"-",ROUNDUP(((((P8*100/107)+$D8)*(1+($A$1*12)))/12)*1.07,0))) -> 2469 | U8: =IF(((P8*$A$1)*15)<$C$1,"-",IF(ROUNDUP((((P8*100/107)*(1+($A$1*15)))/15)*1.07,0)<$B$1,"-",ROUNDUP(((((P8*100/107)+$D8)*(1+($A$1*15)))/15)*1.07,0))) -> 2035 | V8: =IF(((P8*$A$1)*18)<$C$1,"-",IF(ROUNDUP((((P8*100/107)*(1+($A$1*18)))/18)*1.07,0)<$B$1,"-",ROUNDUP(((((P8*100/107)+$D8)*(1+($A$1*18)))/18)*1.07,0))) -> 1746 | W8: =IF(((P8*$A$1)*24)<$C$1,"-",IF(ROUNDUP((((P8*100/107)*(1+($A$1*24)))/24)*1.07,0)<$B$1,"-",ROUNDUP(((((P8*100/107)+$D8)*(1+($A$1*24)))/24)*1.07,0))) -> 1385 | X8: =ROUNDUP($B8*25%,0) -> 7500 | Y8: =$B8-X8 -> 22499 | Z8: =Y8+$D8 -> 24399 | AA8: =IF(((Y8*$A$1)*6)<$C$1,"-",IF(ROUNDUP((((Y8*100/107)*(1+($A$1*6)))/6)*1.07,0)<$B$1,"-",ROUNDUP(((((Y8*100/107)+$D8)*(1+($A$1*6)))/6)*1.07,0))) -> 4371 | AB8: =IF(((Y8*$A$1)*9)<$C$1,"-",IF(ROUNDUP((((Y8*100/107)*(1+($A$1*9)))/9)*1.07,0)<$B$1,"-",ROUNDUP(((((Y8*100/107)+$D8)*(1+($A$1*9)))/9)*1.07,0))) -> 3008 | AC8: =IF(((Y8*$A$1)*12)<$C$1,"-",IF(ROUNDUP((((Y8*100/107)*(1+($A$1*12)))/12)*1.07,0)<$B$1,"-",ROUNDUP(((((Y8*100/107)+$D8)*(1+($A$1*12)))/12)*1.07,0))) -> 2327 | AD8: =IF(((Y8*$A$1)*15)<$C$1,"-",IF(ROUNDUP((((Y8*100/107)*(1+($A$1*15)))/15)*1.07,0)<$B$1,"-",ROUNDUP(((((Y8*100/107)+$D8)*(1+($A$1*15)))/15)*1.07,0))) -> 1918 | AE8: =IF(((Y8*$A$1)*18)<$C$1,"-",IF(ROUNDUP((((Y8*100/107)*(1+($A$1*18)))/18)*1.07,0)<$B$1,"-",ROUNDUP(((((Y8*100/107)+$D8)*(1+($A$1*18)))/18)*1.07,0))) -> 1646 | AF8: =IF(((Y8*$A$1)*24)<$C$1,"-",IF(ROUNDUP((((Y8*100/107)*(1+($A$1*24)))/24)*1.07,0)<$B$1,"-",ROUNDUP(((((Y8*100/107)+$D8)*(1+($A$1*24)))/24)*1.07,0))) -> 1305 | AG8: =ROUNDUP($B8*35%,0) -> 10500 | AH8: =$B8-AG8 -> 19499 | AI8: =AH8+$D8 -> 21399 | AJ8: =IF(((AH8*$A$1)*6)<$C$1,"-",IF(ROUNDUP((((AH8*100/107)*(1+($A$1*6)))/6)*1.07,0)<$B$1,"-",ROUNDUP(((((AH8*100/107)+$D8)*(1+($A$1*6)))/6)*1.07,0))) -> 3837 | AK8: =IF(((AH8*$A$1)*9)<$C$1,"-",IF(ROUNDUP((((AH8*100/107)*(1+($A$1*9)))/9)*1.07,0)<$B$1,"-",ROUNDUP(((((AH8*100/107)+$D8)*(1+($A$1*9)))/9)*1.07,0))) -> 2641 | AL8: =IF(((AH8*$A$1)*12)<$C$1,"-",IF(ROUNDUP((((AH8*100/107)*(1+($A$1*12)))/12)*1.07,0)<$B$1,"-",ROUNDUP(((((AH8*100/107)+$D8)*(1+($A$1*12)))/12)*1.07,0))) -> 2042 | AM8: =IF(((AH8*$A$1)*15)<$C$1,"-",IF(ROUNDUP((((AH8*100/107)*(1+($A$1*15)))/15)*1.07,0)<$B$1,"-",ROUNDUP(((((AH8*100/107)+$D8)*(1+($A$1*15)))/15)*1.07,0))) -> 1684 | AN8: =IF(((AH8*$A$1)*18)<$C$1,"-",IF(ROUNDUP((((AH8*100/107)*(1+($A$1*18)))/18)*1.07,0)<$B$1,"-",ROUNDUP(((((AH8*100/107)+$D8)*(1+($A$1*18)))/18)*1.07,0))) -> 1444 | AO8: =IF(((AH8*$A$1)*24)<$C$1,"-",IF(ROUNDUP((((AH8*100/107)*(1+($A$1*24)))/24)*1.07,0)<$B$1,"-",ROUNDUP(((((AH8*100/107)+$D8)*(1+($A$1*24)))/24)*1.07,0))) -> 1145 | AP8: =ROUNDUP($B8*40%,0) -> 12000 | AQ8: =$B8-AP8 -> 17999 | AR8: =AQ8+$D8 -> 19899 | AS8: =IF(((AQ8*$A$1)*6)<$C$1,"-",IF(ROUNDUP((((AQ8*100/107)*(1+($A$1*6)))/6)*1.07,0)<$B$1,"-",ROUNDUP(((((AQ8*100/107)+$D8)*(1+($A$1*6)))/6)*1.07,0))) -> 3570 | AT8: =IF(((AQ8*$A$1)*9)<$C$1,"-",IF(ROUNDUP((((AQ8*100/107)*(1+($A$1*9)))/9)*1.07,0)<$B$1,"-",ROUNDUP(((((AQ8*100/107)+$D8)*(1+($A$1*9)))/9)*1.07,0))) -> 2457 | AU8: =IF(((AQ8*$A$1)*12)<$C$1,"-",IF(ROUNDUP((((AQ8*100/107)*(1+($A$1*12)))/12)*1.07,0)<$B$1,"-",ROUNDUP(((((AQ8*100/107)+$D8)*(1+($A$1*12)))/12)*1.07,0))) -> 1900 | AV8: =IF(((AQ8*$A$1)*15)<$C$1,"-",IF(ROUNDUP((((AQ8*100/107)*(1+($A$1*15)))/15)*1.07,0)<$B$1,"-",ROUNDUP(((((AQ8*100/107)+$D8)*(1+($A$1*15)))/15)*1.07,0))) -> 1566 | AW8: =IF(((AQ8*$A$1)*18)<$C$1,"-",IF(ROUNDUP((((AQ8*100/107)*(1+($A$1*18)))/18)*1.07,0)<$B$1,"-",ROUNDUP(((((AQ8*100/107)+$D8)*(1+($A$1*18)))/18)*1.07,0))) -> 1344 | AX8: =IF(((AQ8*$A$1)*24)<$C$1,"-",IF(ROUNDUP((((AQ8*100/107)*(1+($A$1*24)))/24)*1.07,0)<$B$1,"-",ROUNDUP(((((AQ8*100/107)+$D8)*(1+($A$1*24)))/24)*1.07,0))) -> 1066
A9: {=IFERROR(INDEX('Product Price'!A:A,SMALL('Product Price'!$D:$D,7)),"")} -> HONOR X7e 6/256 GB | B9: {=IFERROR(INDEX('Product Price'!B:B,SMALL('Product Price'!$D:$D,7)),"")} -> 8999 | C9: {=IFERROR(INDEX('Product Price'!C:C,SMALL('Product Price'!$D:$D,7)),"")} -> 159 | D9: =IF(AND(B9>=3900,B9<=10000),795,IF(AND(B9>=10001,B9<=20000),1450,IF(AND(B9>=20001,B9<=40000),1900,IF(AND(B9>=40001,B9<=60000),2475,IF(AND(B9>=60001,B9<=80000),4025,IF(AND(B9>=80001,B9<=100000),5175,IF(AND(B9>=100001,B9<=120000),6785,""))))))) -> 795 | E9: =IFERROR(B9+D9,"") -> 9794 | F9: =IFERROR(ROUNDUP($B9*15%,0),"") -> 1350 | G9: =$B9-F9 -> 7649 | H9: =$G9+D9 -> 8444 | I9: =IF(((G9*$A$1)*6)<$C$1,"-",IF(ROUNDUP((((G9*100/107)*(1+($A$1*6)))/6)*1.07,0)<$B$1,"-",ROUNDUP(((((G9*100/107)+$D9)*(1+($A$1*6)))/6)*1.07,0))) -> 1515 | J9: =IF(((G9*$A$1)*9)<$C$1,"-",IF(ROUNDUP((((G9*100/107)*(1+($A$1*9)))/9)*1.07,0)<$B$1,"-",ROUNDUP(((((G9*100/107)+$D9)*(1+($A$1*9)))/9)*1.07,0))) -> 1043 | K9: =IF(((G9*$A$1)*12)<$C$1,"-",IF(ROUNDUP((((G9*100/107)*(1+($A$1*12)))/12)*1.07,0)<$B$1,"-",ROUNDUP(((((G9*100/107)+$D9)*(1+($A$1*12)))/12)*1.07,0))) -> 807 | L9: =IF(((G9*$A$1)*15)<$C$1,"-",IF(ROUNDUP((((G9*100/107)*(1+($A$1*15)))/15)*1.07,0)<$B$1,"-",ROUNDUP(((((G9*100/107)+$D9)*(1+($A$1*15)))/15)*1.07,0))) -> 665 | M9: =IF(((G9*$A$1)*18)<$C$1,"-",IF(ROUNDUP((((G9*100/107)*(1+($A$1*18)))/18)*1.07,0)<$B$1,"-",ROUNDUP(((((G9*100/107)+$D9)*(1+($A$1*18)))/18)*1.07,0))) -> 570 | N9: =IF(((G9*$A$1)*24)<$C$1,"-",IF(ROUNDUP((((G9*100/107)*(1+($A$1*24)))/24)*1.07,0)<$B$1,"-",ROUNDUP(((((G9*100/107)+$D9)*(1+($A$1*24)))/24)*1.07,0))) -> 452 | O9: =ROUNDUP($B9*20%,0) -> 1800 | P9: =$B9-O9 -> 7199 | Q9: =P9+$D9 -> 7994 | R9: =IF(((P9*$A$1)*6)<$C$1,"-",IF(ROUNDUP((((P9*100/107)*(1+($A$1*6)))/6)*1.07,0)<$B$1,"-",ROUNDUP(((((P9*100/107)+$D9)*(1+($A$1*6)))/6)*1.07,0))) -> 1435 | S9: =IF(((P9*$A$1)*9)<$C$1,"-",IF(ROUNDUP((((P9*100/107)*(1+($A$1*9)))/9)*1.07,0)<$B$1,"-",ROUNDUP(((((P9*100/107)+$D9)*(1+($A$1*9)))/9)*1.07,0))) -> 987 | T9: =IF(((P9*$A$1)*12)<$C$1,"-",IF(ROUNDUP((((P9*100/107)*(1+($A$1*12)))/12)*1.07,0)<$B$1,"-",ROUNDUP(((((P9*100/107)+$D9)*(1+($A$1*12)))/12)*1.07,0))) -> 764 | U9: =IF(((P9*$A$1)*15)<$C$1,"-",IF(ROUNDUP((((P9*100/107)*(1+($A$1*15)))/15)*1.07,0)<$B$1,"-",ROUNDUP(((((P9*100/107)+$D9)*(1+($A$1*15)))/15)*1.07,0))) -> 630 | V9: =IF(((P9*$A$1)*18)<$C$1,"-",IF(ROUNDUP((((P9*100/107)*(1+($A$1*18)))/18)*1.07,0)<$B$1,"-",ROUNDUP(((((P9*100/107)+$D9)*(1+($A$1*18)))/18)*1.07,0))) -> 540 | W9: =IF(((P9*$A$1)*24)<$C$1,"-",IF(ROUNDUP((((P9*100/107)*(1+($A$1*24)))/24)*1.07,0)<$B$1,"-",ROUNDUP(((((P9*100/107)+$D9)*(1+($A$1*24)))/24)*1.07,0))) -> - | X9: =ROUNDUP($B9*25%,0) -> 2250 | Y9: =$B9-X9 -> 6749 | Z9: =Y9+$D9 -> 7544 | AA9: =IF(((Y9*$A$1)*6)<$C$1,"-",IF(ROUNDUP((((Y9*100/107)*(1+($A$1*6)))/6)*1.07,0)<$B$1,"-",ROUNDUP(((((Y9*100/107)+$D9)*(1+($A$1*6)))/6)*1.07,0))) -> 1355 | AB9: =IF(((Y9*$A$1)*9)<$C$1,"-",IF(ROUNDUP((((Y9*100/107)*(1+($A$1*9)))/9)*1.07,0)<$B$1,"-",ROUNDUP(((((Y9*100/107)+$D9)*(1+($A$1*9)))/9)*1.07,0))) -> 932 | AC9: =IF(((Y9*$A$1)*12)<$C$1,"-",IF(ROUNDUP((((Y9*100/107)*(1+($A$1*12)))/12)*1.07,0)<$B$1,"-",ROUNDUP(((((Y9*100/107)+$D9)*(1+($A$1*12)))/12)*1.07,0))) -> 721 | AD9: =IF(((Y9*$A$1)*15)<$C$1,"-",IF(ROUNDUP((((Y9*100/107)*(1+($A$1*15)))/15)*1.07,0)<$B$1,"-",ROUNDUP(((((Y9*100/107)+$D9)*(1+($A$1*15)))/15)*1.07,0))) -> 595 | AE9: =IF(((Y9*$A$1)*18)<$C$1,"-",IF(ROUNDUP((((Y9*100/107)*(1+($A$1*18)))/18)*1.07,0)<$B$1,"-",ROUNDUP(((((Y9*100/107)+$D9)*(1+($A$1*18)))/18)*1.07,0))) -> 510 | AF9: =IF(((Y9*$A$1)*24)<$C$1,"-",IF(ROUNDUP((((Y9*100/107)*(1+($A$1*24)))/24)*1.07,0)<$B$1,"-",ROUNDUP(((((Y9*100/107)+$D9)*(1+($A$1*24)))/24)*1.07,0))) -> - | AG9: =ROUNDUP($B9*35%,0) -> 3150 | AH9: =$B9-AG9 -> 5849 | AI9: =AH9+$D9 -> 6644 | AJ9: =IF(((AH9*$A$1)*6)<$C$1,"-",IF(ROUNDUP((((AH9*100/107)*(1+($A$1*6)))/6)*1.07,0)<$B$1,"-",ROUNDUP(((((AH9*100/107)+$D9)*(1+($A$1*6)))/6)*1.07,0))) -> 1194 | AK9: =IF(((AH9*$A$1)*9)<$C$1,"-",IF(ROUNDUP((((AH9*100/107)*(1+($A$1*9)))/9)*1.07,0)<$B$1,"-",ROUNDUP(((((AH9*100/107)+$D9)*(1+($A$1*9)))/9)*1.07,0))) -> 822 | AL9: =IF(((AH9*$A$1)*12)<$C$1,"-",IF(ROUNDUP((((AH9*100/107)*(1+($A$1*12)))/12)*1.07,0)<$B$1,"-",ROUNDUP(((((AH9*100/107)+$D9)*(1+($A$1*12)))/12)*1.07,0))) -> 636 | AM9: =IF(((AH9*$A$1)*15)<$C$1,"-",IF(ROUNDUP((((AH9*100/107)*(1+($A$1*15)))/15)*1.07,0)<$B$1,"-",ROUNDUP(((((AH9*100/107)+$D9)*(1+($A$1*15)))/15)*1.07,0))) -> 524 | AN9: =IF(((AH9*$A$1)*18)<$C$1,"-",IF(ROUNDUP((((AH9*100/107)*(1+($A$1*18)))/18)*1.07,0)<$B$1,"-",ROUNDUP(((((AH9*100/107)+$D9)*(1+($A$1*18)))/18)*1.07,0))) -> - | AO9: =IF(((AH9*$A$1)*24)<$C$1,"-",IF(ROUNDUP((((AH9*100/107)*(1+($A$1*24)))/24)*1.07,0)<$B$1,"-",ROUNDUP(((((AH9*100/107)+$D9)*(1+($A$1*24)))/24)*1.07,0))) -> - | AP9: =ROUNDUP($B9*40%,0) -> 3600 | AQ9: =$B9-AP9 -> 5399 | AR9: =AQ9+$D9 -> 6194 | AS9: =IF(((AQ9*$A$1)*6)<$C$1,"-",IF(ROUNDUP((((AQ9*100/107)*(1+($A$1*6)))/6)*1.07,0)<$B$1,"-",ROUNDUP(((((AQ9*100/107)+$D9)*(1+($A$1*6)))/6)*1.07,0))) -> 1114 | AT9: =IF(((AQ9*$A$1)*9)<$C$1,"-",IF(ROUNDUP((((AQ9*100/107)*(1+($A$1*9)))/9)*1.07,0)<$B$1,"-",ROUNDUP(((((AQ9*100/107)+$D9)*(1+($A$1*9)))/9)*1.07,0))) -> 767 | AU9: =IF(((AQ9*$A$1)*12)<$C$1,"-",IF(ROUNDUP((((AQ9*100/107)*(1+($A$1*12)))/12)*1.07,0)<$B$1,"-",ROUNDUP(((((AQ9*100/107)+$D9)*(1+($A$1*12)))/12)*1.07,0))) -> 593 | AV9: =IF(((AQ9*$A$1)*15)<$C$1,"-",IF(ROUNDUP((((AQ9*100/107)*(1+($A$1*15)))/15)*1.07,0)<$B$1,"-",ROUNDUP(((((AQ9*100/107)+$D9)*(1+($A$1*15)))/15)*1.07,0))) -> 489 | AW9: =IF(((AQ9*$A$1)*18)<$C$1,"-",IF(ROUNDUP((((AQ9*100/107)*(1+($A$1*18)))/18)*1.07,0)<$B$1,"-",ROUNDUP(((((AQ9*100/107)+$D9)*(1+($A$1*18)))/18)*1.07,0))) -> - | AX9: =IF(((AQ9*$A$1)*24)<$C$1,"-",IF(ROUNDUP((((AQ9*100/107)*(1+($A$1*24)))/24)*1.07,0)<$B$1,"-",ROUNDUP(((((AQ9*100/107)+$D9)*(1+($A$1*24)))/24)*1.07,0))) -> -
A10: {=IFERROR(INDEX('Product Price'!A:A,SMALL('Product Price'!$D:$D,8)),"")} -> HONOR X7e 6/128 GB | B10: {=IFERROR(INDEX('Product Price'!B:B,SMALL('Product Price'!$D:$D,8)),"")} -> 7999 | C10: {=IFERROR(INDEX('Product Price'!C:C,SMALL('Product Price'!$D:$D,8)),"")} -> 160 | D10: =IF(AND(B10>=3900,B10<=10000),795,IF(AND(B10>=10001,B10<=20000),1450,IF(AND(B10>=20001,B10<=40000),1900,IF(AND(B10>=40001,B10<=60000),2475,IF(AND(B10>=60001,B10<=80000),4025,IF(AND(B10>=80001,B10<=100000),5175,IF(AND(B10>=100001,B10<=120000),6785,""))))))) -> 795 | E10: =IFERROR(B10+D10,"") -> 8794 | F10: =IFERROR(ROUNDUP($B10*15%,0),"") -> 1200 | G10: =$B10-F10 -> 6799 | H10: =$G10+D10 -> 7594 | I10: =IF(((G10*$A$1)*6)<$C$1,"-",IF(ROUNDUP((((G10*100/107)*(1+($A$1*6)))/6)*1.07,0)<$B$1,"-",ROUNDUP(((((G10*100/107)+$D10)*(1+($A$1*6)))/6)*1.07,0))) -> 1363 | J10: =IF(((G10*$A$1)*9)<$C$1,"-",IF(ROUNDUP((((G10*100/107)*(1+($A$1*9)))/9)*1.07,0)<$B$1,"-",ROUNDUP(((((G10*100/107)+$D10)*(1+($A$1*9)))/9)*1.07,0))) -> 938 | K10: =IF(((G10*$A$1)*12)<$C$1,"-",IF(ROUNDUP((((G10*100/107)*(1+($A$1*12)))/12)*1.07,0)<$B$1,"-",ROUNDUP(((((G10*100/107)+$D10)*(1+($A$1*12)))/12)*1.07,0))) -> 726 | L10: =IF(((G10*$A$1)*15)<$C$1,"-",IF(ROUNDUP((((G10*100/107)*(1+($A$1*15)))/15)*1.07,0)<$B$1,"-",ROUNDUP(((((G10*100/107)+$D10)*(1+($A$1*15)))/15)*1.07,0))) -> 598 | M10: =IF(((G10*$A$1)*18)<$C$1,"-",IF(ROUNDUP((((G10*100/107)*(1+($A$1*18)))/18)*1.07,0)<$B$1,"-",ROUNDUP(((((G10*100/107)+$D10)*(1+($A$1*18)))/18)*1.07,0))) -> 513 | N10: =IF(((G10*$A$1)*24)<$C$1,"-",IF(ROUNDUP((((G10*100/107)*(1+($A$1*24)))/24)*1.07,0)<$B$1,"-",ROUNDUP(((((G10*100/107)+$D10)*(1+($A$1*24)))/24)*1.07,0))) -> - | O10: =ROUNDUP($B10*20%,0) -> 1600 | P10: =$B10-O10 -> 6399 | Q10: =P10+$D10 -> 7194 | R10: =IF(((P10*$A$1)*6)<$C$1,"-",IF(ROUNDUP((((P10*100/107)*(1+($A$1*6)))/6)*1.07,0)<$B$1,"-",ROUNDUP(((((P10*100/107)+$D10)*(1+($A$1*6)))/6)*1.07,0))) -> 1292 | S10: =IF(((P10*$A$1)*9)<$C$1,"-",IF(ROUNDUP((((P10*100/107)*(1+($A$1*9)))/9)*1.07,0)<$B$1,"-",ROUNDUP(((((P10*100/107)+$D10)*(1+($A$1*9)))/9)*1.07,0))) -> 889 | T10: =IF(((P10*$A$1)*12)<$C$1,"-",IF(ROUNDUP((((P10*100/107)*(1+($A$1*12)))/12)*1.07,0)<$B$1,"-",ROUNDUP(((((P10*100/107)+$D10)*(1+($A$1*12)))/12)*1.07,0))) -> 688 | U10: =IF(((P10*$A$1)*15)<$C$1,"-",IF(ROUNDUP((((P10*100/107)*(1+($A$1*15)))/15)*1.07,0)<$B$1,"-",ROUNDUP(((((P10*100/107)+$D10)*(1+($A$1*15)))/15)*1.07,0))) -> 567 | V10: =IF(((P10*$A$1)*18)<$C$1,"-",IF(ROUNDUP((((P10*100/107)*(1+($A$1*18)))/18)*1.07,0)<$B$1,"-",ROUNDUP(((((P10*100/107)+$D10)*(1+($A$1*18)))/18)*1.07,0))) -> 487 | W10: =IF(((P10*$A$1)*24)<$C$1,"-",IF(ROUNDUP((((P10*100/107)*(1+($A$1*24)))/24)*1.07,0)<$B$1,"-",ROUNDUP(((((P10*100/107)+$D10)*(1+($A$1*24)))/24)*1.07,0))) -> - | X10: =ROUNDUP($B10*25%,0) -> 2000 | Y10: =$B10-X10 -> 5999 | Z10: =Y10+$D10 -> 6794 | AA10: =IF(((Y10*$A$1)*6)<$C$1,"-",IF(ROUNDUP((((Y10*100/107)*(1+($A$1*6)))/6)*1.07,0)<$B$1,"-",ROUNDUP(((((Y10*100/107)+$D10)*(1+($A$1*6)))/6)*1.07,0))) -> 1221 | AB10: =IF(((Y10*$A$1)*9)<$C$1,"-",IF(ROUNDUP((((Y10*100/107)*(1+($A$1*9)))/9)*1.07,0)<$B$1,"-",ROUNDUP(((((Y10*100/107)+$D10)*(1+($A$1*9)))/9)*1.07,0))) -> 840 | AC10: =IF(((Y10*$A$1)*12)<$C$1,"-",IF(ROUNDUP((((Y10*100/107)*(1+($A$1*12)))/12)*1.07,0)<$B$1,"-",ROUNDUP(((((Y10*100/107)+$D10)*(1+($A$1*12)))/12)*1.07,0))) -> 650 | AD10: =IF(((Y10*$A$1)*15)<$C$1,"-",IF(ROUNDUP((((Y10*100/107)*(1+($A$1*15)))/15)*1.07,0)<$B$1,"-",ROUNDUP(((((Y10*100/107)+$D10)*(1+($A$1*15)))/15)*1.07,0))) -> 536 | AE10: =IF(((Y10*$A$1)*18)<$C$1,"-",IF(ROUNDUP((((Y10*100/107)*(1+($A$1*18)))/18)*1.07,0)<$B$1,"-",ROUNDUP(((((Y10*100/107)+$D10)*(1+($A$1*18)))/18)*1.07,0))) -> 460 | AF10: =IF(((Y10*$A$1)*24)<$C$1,"-",IF(ROUNDUP((((Y10*100/107)*(1+($A$1*24)))/24)*1.07,0)<$B$1,"-",ROUNDUP(((((Y10*100/107)+$D10)*(1+($A$1*24)))/24)*1.07,0))) -> - | AG10: =ROUNDUP($B10*35%,0) -> 2800 | AH10: =$B10-AG10 -> 5199 | AI10: =AH10+$D10 -> 5994 | AJ10: =IF(((AH10*$A$1)*6)<$C$1,"-",IF(ROUNDUP((((AH10*100/107)*(1+($A$1*6)))/6)*1.07,0)<$B$1,"-",ROUNDUP(((((AH10*100/107)+$D10)*(1+($A$1*6)))/6)*1.07,0))) -> 1078 | AK10: =IF(((AH10*$A$1)*9)<$C$1,"-",IF(ROUNDUP((((AH10*100/107)*(1+($A$1*9)))/9)*1.07,0)<$B$1,"-",ROUNDUP(((((AH10*100/107)+$D10)*(1+($A$1*9)))/9)*1.07,0))) -> 742 | AL10: =IF(((AH10*$A$1)*12)<$C$1,"-",IF(ROUNDUP((((AH10*100/107)*(1+($A$1*12)))/12)*1.07,0)<$B$1,"-",ROUNDUP(((((AH10*100/107)+$D10)*(1+($A$1*12)))/12)*1.07,0))) -> 574 | AM10: =IF(((AH10*$A$1)*15)<$C$1,"-",IF(ROUNDUP((((AH10*100/107)*(1+($A$1*15)))/15)*1.07,0)<$B$1,"-",ROUNDUP(((((AH10*100/107)+$D10)*(1+($A$1*15)))/15)*1.07,0))) -> 473 | AN10: =IF(((AH10*$A$1)*18)<$C$1,"-",IF(ROUNDUP((((AH10*100/107)*(1+($A$1*18)))/18)*1.07,0)<$B$1,"-",ROUNDUP(((((AH10*100/107)+$D10)*(1+($A$1*18)))/18)*1.07,0))) -> - | AO10: =IF(((AH10*$A$1)*24)<$C$1,"-",IF(ROUNDUP((((AH10*100/107)*(1+($A$1*24)))/24)*1.07,0)<$B$1,"-",ROUNDUP(((((AH10*100/107)+$D10)*(1+($A$1*24)))/24)*1.07,0))) -> - | AP10: =ROUNDUP($B10*40%,0) -> 3200 | AQ10: =$B10-AP10 -> 4799 | AR10: =AQ10+$D10 -> 5594 | AS10: =IF(((AQ10*$A$1)*6)<$C$1,"-",IF(ROUNDUP((((AQ10*100/107)*(1+($A$1*6)))/6)*1.07,0)<$B$1,"-",ROUNDUP(((((AQ10*100/107)+$D10)*(1+($A$1*6)))/6)*1.07,0))) -> 1007 | AT10: =IF(((AQ10*$A$1)*9)<$C$1,"-",IF(ROUNDUP((((AQ10*100/107)*(1+($A$1*9)))/9)*1.07,0)<$B$1,"-",ROUNDUP(((((AQ10*100/107)+$D10)*(1+($A$1*9)))/9)*1.07,0))) -> 693 | AU10: =IF(((AQ10*$A$1)*12)<$C$1,"-",IF(ROUNDUP((((AQ10*100/107)*(1+($A$1*12)))/12)*1.07,0)<$B$1,"-",ROUNDUP(((((AQ10*100/107)+$D10)*(1+($A$1*12)))/12)*1.07,0))) -> 536 | AV10: =IF(((AQ10*$A$1)*15)<$C$1,"-",IF(ROUNDUP((((AQ10*100/107)*(1+($A$1*15)))/15)*1.07,0)<$B$1,"-",ROUNDUP(((((AQ10*100/107)+$D10)*(1+($A$1*15)))/15)*1.07,0))) -> - | AW10: =IF(((AQ10*$A$1)*18)<$C$1,"-",IF(ROUNDUP((((AQ10*100/107)*(1+($A$1*18)))/18)*1.07,0)<$B$1,"-",ROUNDUP(((((AQ10*100/107)+$D10)*(1+($A$1*18)))/18)*1.07,0))) -> - | AX10: =IF(((AQ10*$A$1)*24)<$C$1,"-",IF(ROUNDUP((((AQ10*100/107)*(1+($A$1*24)))/24)*1.07,0)<$B$1,"-",ROUNDUP(((((AQ10*100/107)+$D10)*(1+($A$1*24)))/24)*1.07,0))) -> -
A11: {=IFERROR(INDEX('Product Price'!A:A,SMALL('Product Price'!$D:$D,9)),"")} -> HONOR Pad X8b 6/128 GB | B11: {=IFERROR(INDEX('Product Price'!B:B,SMALL('Product Price'!$D:$D,9)),"")} -> 8999 | C11: {=IFERROR(INDEX('Product Price'!C:C,SMALL('Product Price'!$D:$D,9)),"")} -> 6 | D11: =IF(AND(B11>=3900,B11<=10000),795,IF(AND(B11>=10001,B11<=20000),1450,IF(AND(B11>=20001,B11<=40000),1900,IF(AND(B11>=40001,B11<=60000),2475,IF(AND(B11>=60001,B11<=80000),4025,IF(AND(B11>=80001,B11<=100000),5175,IF(AND(B11>=100001,B11<=120000),6785,""))))))) -> 795 | E11: =IFERROR(B11+D11,"") -> 9794 | F11: =IFERROR(ROUNDUP($B11*15%,0),"") -> 1350 | G11: =$B11-F11 -> 7649 | H11: =$G11+D11 -> 8444 | I11: =IF(((G11*$A$1)*6)<$C$1,"-",IF(ROUNDUP((((G11*100/107)*(1+($A$1*6)))/6)*1.07,0)<$B$1,"-",ROUNDUP(((((G11*100/107)+$D11)*(1+($A$1*6)))/6)*1.07,0))) -> 1515 | J11: =IF(((G11*$A$1)*9)<$C$1,"-",IF(ROUNDUP((((G11*100/107)*(1+($A$1*9)))/9)*1.07,0)<$B$1,"-",ROUNDUP(((((G11*100/107)+$D11)*(1+($A$1*9)))/9)*1.07,0))) -> 1043 | K11: =IF(((G11*$A$1)*12)<$C$1,"-",IF(ROUNDUP((((G11*100/107)*(1+($A$1*12)))/12)*1.07,0)<$B$1,"-",ROUNDUP(((((G11*100/107)+$D11)*(1+($A$1*12)))/12)*1.07,0))) -> 807 | L11: =IF(((G11*$A$1)*15)<$C$1,"-",IF(ROUNDUP((((G11*100/107)*(1+($A$1*15)))/15)*1.07,0)<$B$1,"-",ROUNDUP(((((G11*100/107)+$D11)*(1+($A$1*15)))/15)*1.07,0))) -> 665 | M11: =IF(((G11*$A$1)*18)<$C$1,"-",IF(ROUNDUP((((G11*100/107)*(1+($A$1*18)))/18)*1.07,0)<$B$1,"-",ROUNDUP(((((G11*100/107)+$D11)*(1+($A$1*18)))/18)*1.07,0))) -> 570 | N11: =IF(((G11*$A$1)*24)<$C$1,"-",IF(ROUNDUP((((G11*100/107)*(1+($A$1*24)))/24)*1.07,0)<$B$1,"-",ROUNDUP(((((G11*100/107)+$D11)*(1+($A$1*24)))/24)*1.07,0))) -> 452 | O11: =ROUNDUP($B11*20%,0) -> 1800 | P11: =$B11-O11 -> 7199 | Q11: =P11+$D11 -> 7994 | R11: =IF(((P11*$A$1)*6)<$C$1,"-",IF(ROUNDUP((((P11*100/107)*(1+($A$1*6)))/6)*1.07,0)<$B$1,"-",ROUNDUP(((((P11*100/107)+$D11)*(1+($A$1*6)))/6)*1.07,0))) -> 1435 | S11: =IF(((P11*$A$1)*9)<$C$1,"-",IF(ROUNDUP((((P11*100/107)*(1+($A$1*9)))/9)*1.07,0)<$B$1,"-",ROUNDUP(((((P11*100/107)+$D11)*(1+($A$1*9)))/9)*1.07,0))) -> 987 | T11: =IF(((P11*$A$1)*12)<$C$1,"-",IF(ROUNDUP((((P11*100/107)*(1+($A$1*12)))/12)*1.07,0)<$B$1,"-",ROUNDUP(((((P11*100/107)+$D11)*(1+($A$1*12)))/12)*1.07,0))) -> 764 | U11: =IF(((P11*$A$1)*15)<$C$1,"-",IF(ROUNDUP((((P11*100/107)*(1+($A$1*15)))/15)*1.07,0)<$B$1,"-",ROUNDUP(((((P11*100/107)+$D11)*(1+($A$1*15)))/15)*1.07,0))) -> 630 | V11: =IF(((P11*$A$1)*18)<$C$1,"-",IF(ROUNDUP((((P11*100/107)*(1+($A$1*18)))/18)*1.07,0)<$B$1,"-",ROUNDUP(((((P11*100/107)+$D11)*(1+($A$1*18)))/18)*1.07,0))) -> 540 | W11: =IF(((P11*$A$1)*24)<$C$1,"-",IF(ROUNDUP((((P11*100/107)*(1+($A$1*24)))/24)*1.07,0)<$B$1,"-",ROUNDUP(((((P11*100/107)+$D11)*(1+($A$1*24)))/24)*1.07,0))) -> - | X11: =ROUNDUP($B11*25%,0) -> 2250 | Y11: =$B11-X11 -> 6749 | Z11: =Y11+$D11 -> 7544 | AA11: =IF(((Y11*$A$1)*6)<$C$1,"-",IF(ROUNDUP((((Y11*100/107)*(1+($A$1*6)))/6)*1.07,0)<$B$1,"-",ROUNDUP(((((Y11*100/107)+$D11)*(1+($A$1*6)))/6)*1.07,0))) -> 1355 | AB11: =IF(((Y11*$A$1)*9)<$C$1,"-",IF(ROUNDUP((((Y11*100/107)*(1+($A$1*9)))/9)*1.07,0)<$B$1,"-",ROUNDUP(((((Y11*100/107)+$D11)*(1+($A$1*9)))/9)*1.07,0))) -> 932 | AC11: =IF(((Y11*$A$1)*12)<$C$1,"-",IF(ROUNDUP((((Y11*100/107)*(1+($A$1*12)))/12)*1.07,0)<$B$1,"-",ROUNDUP(((((Y11*100/107)+$D11)*(1+($A$1*12)))/12)*1.07,0))) -> 721 | AD11: =IF(((Y11*$A$1)*15)<$C$1,"-",IF(ROUNDUP((((Y11*100/107)*(1+($A$1*15)))/15)*1.07,0)<$B$1,"-",ROUNDUP(((((Y11*100/107)+$D11)*(1+($A$1*15)))/15)*1.07,0))) -> 595 | AE11: =IF(((Y11*$A$1)*18)<$C$1,"-",IF(ROUNDUP((((Y11*100/107)*(1+($A$1*18)))/18)*1.07,0)<$B$1,"-",ROUNDUP(((((Y11*100/107)+$D11)*(1+($A$1*18)))/18)*1.07,0))) -> 510 | AF11: =IF(((Y11*$A$1)*24)<$C$1,"-",IF(ROUNDUP((((Y11*100/107)*(1+($A$1*24)))/24)*1.07,0)<$B$1,"-",ROUNDUP(((((Y11*100/107)+$D11)*(1+($A$1*24)))/24)*1.07,0))) -> - | AG11: =ROUNDUP($B11*35%,0) -> 3150 | AH11: =$B11-AG11 -> 5849 | AI11: =AH11+$D11 -> 6644 | AJ11: =IF(((AH11*$A$1)*6)<$C$1,"-",IF(ROUNDUP((((AH11*100/107)*(1+($A$1*6)))/6)*1.07,0)<$B$1,"-",ROUNDUP(((((AH11*100/107)+$D11)*(1+($A$1*6)))/6)*1.07,0))) -> 1194 | AK11: =IF(((AH11*$A$1)*9)<$C$1,"-",IF(ROUNDUP((((AH11*100/107)*(1+($A$1*9)))/9)*1.07,0)<$B$1,"-",ROUNDUP(((((AH11*100/107)+$D11)*(1+($A$1*9)))/9)*1.07,0))) -> 822 | AL11: =IF(((AH11*$A$1)*12)<$C$1,"-",IF(ROUNDUP((((AH11*100/107)*(1+($A$1*12)))/12)*1.07,0)<$B$1,"-",ROUNDUP(((((AH11*100/107)+$D11)*(1+($A$1*12)))/12)*1.07,0))) -> 636 | AM11: =IF(((AH11*$A$1)*15)<$C$1,"-",IF(ROUNDUP((((AH11*100/107)*(1+($A$1*15)))/15)*1.07,0)<$B$1,"-",ROUNDUP(((((AH11*100/107)+$D11)*(1+($A$1*15)))/15)*1.07,0))) -> 524 | AN11: =IF(((AH11*$A$1)*18)<$C$1,"-",IF(ROUNDUP((((AH11*100/107)*(1+($A$1*18)))/18)*1.07,0)<$B$1,"-",ROUNDUP(((((AH11*100/107)+$D11)*(1+($A$1*18)))/18)*1.07,0))) -> - | AO11: =IF(((AH11*$A$1)*24)<$C$1,"-",IF(ROUNDUP((((AH11*100/107)*(1+($A$1*24)))/24)*1.07,0)<$B$1,"-",ROUNDUP(((((AH11*100/107)+$D11)*(1+($A$1*24)))/24)*1.07,0))) -> - | AP11: =ROUNDUP($B11*40%,0) -> 3600 | AQ11: =$B11-AP11 -> 5399 | AR11: =AQ11+$D11 -> 6194 | AS11: =IF(((AQ11*$A$1)*6)<$C$1,"-",IF(ROUNDUP((((AQ11*100/107)*(1+($A$1*6)))/6)*1.07,0)<$B$1,"-",ROUNDUP(((((AQ11*100/107)+$D11)*(1+($A$1*6)))/6)*1.07,0))) -> 1114 | AT11: =IF(((AQ11*$A$1)*9)<$C$1,"-",IF(ROUNDUP((((AQ11*100/107)*(1+($A$1*9)))/9)*1.07,0)<$B$1,"-",ROUNDUP(((((AQ11*100/107)+$D11)*(1+($A$1*9)))/9)*1.07,0))) -> 767 | AU11: =IF(((AQ11*$A$1)*12)<$C$1,"-",IF(ROUNDUP((((AQ11*100/107)*(1+($A$1*12)))/12)*1.07,0)<$B$1,"-",ROUNDUP(((((AQ11*100/107)+$D11)*(1+($A$1*12)))/12)*1.07,0))) -> 593 | AV11: =IF(((AQ11*$A$1)*15)<$C$1,"-",IF(ROUNDUP((((AQ11*100/107)*(1+($A$1*15)))/15)*1.07,0)<$B$1,"-",ROUNDUP(((((AQ11*100/107)+$D11)*(1+($A$1*15)))/15)*1.07,0))) -> 489 | AW11: =IF(((AQ11*$A$1)*18)<$C$1,"-",IF(ROUNDUP((((AQ11*100/107)*(1+($A$1*18)))/18)*1.07,0)<$B$1,"-",ROUNDUP(((((AQ11*100/107)+$D11)*(1+($A$1*18)))/18)*1.07,0))) -> - | AX11: =IF(((AQ11*$A$1)*24)<$C$1,"-",IF(ROUNDUP((((AQ11*100/107)*(1+($A$1*24)))/24)*1.07,0)<$B$1,"-",ROUNDUP(((((AQ11*100/107)+$D11)*(1+($A$1*24)))/24)*1.07,0))) -> -
